2014-07-23 00:53:57,826 [Thread-3:-1256195264] [django.request:143] [WARNING]- Not Found: /favicon.ico
2014-07-23 01:35:59,056 [Thread-5:-1245709504] [django.request:224] [ERROR]- Internal Server Error: /test1/
Traceback (most recent call last):
  File "/usr/local/lib/python2.7/dist-packages/django/core/handlers/base.py", line 112, in get_response
    response = wrapped_callback(request, *callback_args, **callback_kwargs)
  File "/usr/local/lib/python2.7/dist-packages/django/bin/myste/opt/views.py", line 28, in opt_data
    return render_to_response('test1.html',{'getsiteinfo':s})
  File "/usr/local/lib/python2.7/dist-packages/django/shortcuts/__init__.py", line 29, in render_to_response
    return HttpResponse(loader.render_to_string(*args, **kwargs), **httpresponse_kwargs)
  File "/usr/local/lib/python2.7/dist-packages/django/template/loader.py", line 162, in render_to_string
    t = get_template(template_name)
  File "/usr/local/lib/python2.7/dist-packages/django/template/loader.py", line 138, in get_template
    template, origin = find_template(template_name)
  File "/usr/local/lib/python2.7/dist-packages/django/template/loader.py", line 131, in find_template
    raise TemplateDoesNotExist(name)
TemplateDoesNotExist: test1.html
2014-07-23 01:37:13,468 [Thread-3:-1256195264] [django.request:143] [WARNING]- Not Found: /test1/common.css
2014-07-23 01:37:20,215 [Thread-5:-1245709504] [django.request:143] [WARNING]- Not Found: /test1/common.css
2014-07-23 01:37:23,012 [Thread-7:-1275073728] [django.request:143] [WARNING]- Not Found: /test1/common.css
2014-07-23 01:37:39,245 [Thread-9:-1275073728] [django.request:143] [WARNING]- Not Found: /test1/common.css
2014-07-23 01:37:42,316 [Thread-11:-1275073728] [django.request:143] [WARNING]- Not Found: /test1/common.css
2014-07-23 01:37:46,742 [Thread-13:-1275073728] [django.request:143] [WARNING]- Not Found: /test1/common.css
2014-07-23 01:39:18,248 [Thread-3:-1256195264] [django.request:143] [WARNING]- Not Found: /test1/common.css
2014-07-23 01:39:48,542 [Thread-3:-1255146688] [django.request:143] [WARNING]- Not Found: /test1/common.css
2014-07-23 01:44:16,330 [Thread-6:-1255146688] [django.request:143] [WARNING]- Not Found: /test1/common.css
2014-07-23 01:50:08,249 [Thread-3:-1255146688] [django.request:143] [WARNING]- Not Found: /test1/common.css
2014-07-23 01:50:10,371 [Thread-5:-1255146688] [django.request:143] [WARNING]- Not Found: /test1/common.css
2014-07-23 01:50:28,812 [Thread-7:-1244660928] [django.request:224] [ERROR]- Internal Server Error: /test1/
Traceback (most recent call last):
  File "/usr/local/lib/python2.7/dist-packages/django/core/handlers/base.py", line 112, in get_response
    response = wrapped_callback(request, *callback_args, **callback_kwargs)
  File "/usr/local/lib/python2.7/dist-packages/django/bin/myste/opt/views.py", line 28, in opt_data
    return render_to_response('test1.html',{'getsiteinfo':s})
  File "/usr/local/lib/python2.7/dist-packages/django/shortcuts/__init__.py", line 29, in render_to_response
    return HttpResponse(loader.render_to_string(*args, **kwargs), **httpresponse_kwargs)
  File "/usr/local/lib/python2.7/dist-packages/django/template/loader.py", line 162, in render_to_string
    t = get_template(template_name)
  File "/usr/local/lib/python2.7/dist-packages/django/template/loader.py", line 138, in get_template
    template, origin = find_template(template_name)
  File "/usr/local/lib/python2.7/dist-packages/django/template/loader.py", line 131, in find_template
    raise TemplateDoesNotExist(name)
TemplateDoesNotExist: test1.html
2014-07-23 01:50:31,411 [Thread-8:-1255146688] [django.request:224] [ERROR]- Internal Server Error: /test1/
Traceback (most recent call last):
  File "/usr/local/lib/python2.7/dist-packages/django/core/handlers/base.py", line 112, in get_response
    response = wrapped_callback(request, *callback_args, **callback_kwargs)
  File "/usr/local/lib/python2.7/dist-packages/django/bin/myste/opt/views.py", line 28, in opt_data
    return render_to_response('test1.html',{'getsiteinfo':s})
  File "/usr/local/lib/python2.7/dist-packages/django/shortcuts/__init__.py", line 29, in render_to_response
    return HttpResponse(loader.render_to_string(*args, **kwargs), **httpresponse_kwargs)
  File "/usr/local/lib/python2.7/dist-packages/django/template/loader.py", line 162, in render_to_string
    t = get_template(template_name)
  File "/usr/local/lib/python2.7/dist-packages/django/template/loader.py", line 138, in get_template
    template, origin = find_template(template_name)
  File "/usr/local/lib/python2.7/dist-packages/django/template/loader.py", line 131, in find_template
    raise TemplateDoesNotExist(name)
TemplateDoesNotExist: test1.html
2014-07-23 01:58:19,538 [Thread-3:-1244660928] [django.request:143] [WARNING]- Not Found: /test1/common.css
2014-07-23 02:07:01,649 [Thread-5:-1244660928] [django.request:143] [WARNING]- Not Found: /test1/common.css
2014-07-23 02:07:02,407 [Thread-7:-1244660928] [django.request:143] [WARNING]- Not Found: /test1/common.css
2014-07-23 02:08:56,536 [Thread-3:-1256195264] [django.request:143] [WARNING]- Not Found: /test1/common.css
2014-07-23 02:08:59,695 [Thread-5:-1256195264] [django.request:143] [WARNING]- Not Found: /test1/common.css
2014-07-23 02:09:05,788 [Thread-7:-1245709504] [django.request:143] [WARNING]- Not Found: /test1/common.css
2014-07-23 02:10:01,322 [Thread-9:-1256195264] [django.request:143] [WARNING]- Not Found: /test1/common.css
2014-07-23 02:10:04,604 [Thread-11:-1256195264] [django.request:143] [WARNING]- Not Found: /test1/common.css
2014-07-23 02:17:19,576 [Thread-3:-1255146688] [django.request:143] [WARNING]- Not Found: /test1/static/common.css
2014-07-23 02:17:23,287 [Thread-5:-1255146688] [django.request:143] [WARNING]- Not Found: /test1/static/common.css
2014-07-23 02:17:25,660 [Thread-7:-1244660928] [django.request:143] [WARNING]- Not Found: /test1/static/common.css
2014-07-23 02:17:26,831 [Thread-9:-1244660928] [django.request:143] [WARNING]- Not Found: /test1/static/common.css
2014-07-23 02:17:27,878 [Thread-11:-1244660928] [django.request:143] [WARNING]- Not Found: /test1/static/common.css
2014-07-23 02:19:56,228 [Thread-3:-1256195264] [django.request:143] [WARNING]- Not Found: /test1/common.css
2014-07-23 02:28:26,799 [Thread-3:-1255146688] [django.request:143] [WARNING]- Not Found: /test1/common.css
2014-07-23 02:29:21,745 [Thread-3:-1255146688] [django.request:143] [WARNING]- Not Found: /common.css
2014-07-23 02:30:08,996 [Thread-3:-1255146688] [django.request:143] [WARNING]- Not Found: /static/ommon.css
2014-07-23 02:37:27,881 [Thread-1:-1244923072] [django.request:224] [ERROR]- Internal Server Error: /test1/
Traceback (most recent call last):
  File "/usr/local/lib/python2.7/dist-packages/django/core/handlers/base.py", line 99, in get_response
    resolver_match = resolver.resolve(request.path_info)
  File "/usr/local/lib/python2.7/dist-packages/django/core/urlresolvers.py", line 337, in resolve
    for pattern in self.url_patterns:
  File "/usr/local/lib/python2.7/dist-packages/django/core/urlresolvers.py", line 365, in url_patterns
    patterns = getattr(self.urlconf_module, "urlpatterns", self.urlconf_module)
  File "/usr/local/lib/python2.7/dist-packages/django/core/urlresolvers.py", line 360, in urlconf_module
    self._urlconf_module = import_module(self.urlconf_name)
  File "/usr/local/lib/python2.7/dist-packages/django/utils/importlib.py", line 40, in import_module
    __import__(name)
  File "/usr/local/lib/python2.7/dist-packages/django/bin/myste/myste/urls.py", line 2
    from django.conf import settingfrom django.conf import setting
                                             ^
SyntaxError: invalid syntax
2014-07-23 02:38:26,597 [Thread-5:-1255146688] [django.request:224] [ERROR]- Internal Server Error: /test1/
Traceback (most recent call last):
  File "/usr/local/lib/python2.7/dist-packages/django/core/handlers/base.py", line 99, in get_response
    resolver_match = resolver.resolve(request.path_info)
  File "/usr/local/lib/python2.7/dist-packages/django/core/urlresolvers.py", line 337, in resolve
    for pattern in self.url_patterns:
  File "/usr/local/lib/python2.7/dist-packages/django/core/urlresolvers.py", line 365, in url_patterns
    patterns = getattr(self.urlconf_module, "urlpatterns", self.urlconf_module)
  File "/usr/local/lib/python2.7/dist-packages/django/core/urlresolvers.py", line 360, in urlconf_module
    self._urlconf_module = import_module(self.urlconf_name)
  File "/usr/local/lib/python2.7/dist-packages/django/utils/importlib.py", line 40, in import_module
    __import__(name)
  File "/usr/local/lib/python2.7/dist-packages/django/bin/myste/myste/urls.py", line 2, in <module>
    from django.conf import setting
ImportError: cannot import name setting
2014-07-23 02:38:49,801 [Thread-7:-1255146688] [django.request:143] [WARNING]- Not Found: /static/ommon.css
2014-07-23 02:40:02,671 [Thread-3:-1244923072] [django.request:143] [WARNING]- Not Found: /site_media/ommon.css
2014-07-23 02:41:10,942 [Thread-5:-1244923072] [django.request:143] [WARNING]- Not Found: /site_media/ommon.css
2014-07-23 02:42:52,596 [Thread-7:-1255146688] [django.request:143] [WARNING]- Not Found: /site_media/ommon.css
2014-07-23 02:47:09,077 [Thread-9:-1244923072] [django.request:143] [WARNING]- Not Found: /site_media/ommon.css
2014-07-23 02:47:12,671 [Thread-11:-1255146688] [django.request:143] [WARNING]- Not Found: /site_media/ommon.css
2014-07-23 02:49:15,059 [Thread-13:-1244923072] [django.request:143] [WARNING]- Not Found: /site_media/ommon.css
2014-07-23 02:49:37,940 [Thread-15:-1244923072] [django.request:143] [WARNING]- Not Found: /site_media/ommon.css
2014-07-23 02:49:38,990 [Thread-17:-1244923072] [django.request:143] [WARNING]- Not Found: /site_media/ommon.css
2014-07-23 02:52:05,805 [Thread-3:-1255146688] [django.request:143] [WARNING]- Not Found: /site_media/ommon.css
2014-07-23 03:01:35,542 [Thread-6:-1255146688] [django.request:143] [WARNING]- Not Found: /site_media/ommon.css
2014-07-23 03:13:34,110 [Thread-1:-1245709504] [django.request:224] [ERROR]- Internal Server Error: /test1/
Traceback (most recent call last):
  File "/usr/local/lib/python2.7/dist-packages/django/core/handlers/base.py", line 99, in get_response
    resolver_match = resolver.resolve(request.path_info)
  File "/usr/local/lib/python2.7/dist-packages/django/core/urlresolvers.py", line 337, in resolve
    for pattern in self.url_patterns:
  File "/usr/local/lib/python2.7/dist-packages/django/core/urlresolvers.py", line 365, in url_patterns
    patterns = getattr(self.urlconf_module, "urlpatterns", self.urlconf_module)
  File "/usr/local/lib/python2.7/dist-packages/django/core/urlresolvers.py", line 360, in urlconf_module
    self._urlconf_module = import_module(self.urlconf_name)
  File "/usr/local/lib/python2.7/dist-packages/django/utils/importlib.py", line 40, in import_module
    __import__(name)
  File "/usr/local/lib/python2.7/dist-packages/django/bin/myste/myste/urls.py", line 15, in <module>
    urlpatterns +=staticfiles_urlpatterns
TypeError: 'function' object is not iterable
2014-07-23 03:14:21,636 [Thread-4:-1245709504] [django.request:143] [WARNING]- Not Found: /site_media/ommon.css
2014-07-23 03:15:18,807 [Thread-3:-1244660928] [django.request:143] [WARNING]- Not Found: /test1/ommon.css
2014-07-23 07:36:36,416 [Thread-1:-1244976320] [django.request:224] [ERROR]- Internal Server Error: /test1/
Traceback (most recent call last):
  File "/usr/local/lib/python2.7/dist-packages/django/core/handlers/base.py", line 112, in get_response
    response = wrapped_callback(request, *callback_args, **callback_kwargs)
  File "/usr/local/lib/python2.7/dist-packages/django/bin/myste/opt/views.py", line 20, in opt_data
    print json.dumps(i.date)
  File "/usr/lib/python2.7/json/__init__.py", line 243, in dumps
    return _default_encoder.encode(obj)
  File "/usr/lib/python2.7/json/encoder.py", line 207, in encode
    chunks = self.iterencode(o, _one_shot=True)
  File "/usr/lib/python2.7/json/encoder.py", line 270, in iterencode
    return _iterencode(o, 0)
  File "/usr/lib/python2.7/json/encoder.py", line 184, in default
    raise TypeError(repr(o) + " is not JSON serializable")
TypeError: datetime.datetime(2014, 7, 23, 14, 56, 25) is not JSON serializable
2014-07-23 07:46:19,067 [Thread-1:-1244660928] [django.request:224] [ERROR]- Internal Server Error: /test1/
Traceback (most recent call last):
  File "/usr/local/lib/python2.7/dist-packages/django/core/handlers/base.py", line 112, in get_response
    response = wrapped_callback(request, *callback_args, **callback_kwargs)
  File "/usr/local/lib/python2.7/dist-packages/django/bin/myste/opt/views.py", line 22, in opt_data
    s=json.dumps(p)
  File "/usr/lib/python2.7/json/__init__.py", line 243, in dumps
    return _default_encoder.encode(obj)
  File "/usr/lib/python2.7/json/encoder.py", line 207, in encode
    chunks = self.iterencode(o, _one_shot=True)
  File "/usr/lib/python2.7/json/encoder.py", line 270, in iterencode
    return _iterencode(o, 0)
  File "/usr/lib/python2.7/json/encoder.py", line 184, in default
    raise TypeError(repr(o) + " is not JSON serializable")
TypeError: datetime.datetime(2014, 7, 23, 14, 56, 25) is not JSON serializable
2014-07-23 07:55:25,992 [Thread-1:-1244660928] [django.request:224] [ERROR]- Internal Server Error: /test1/
Traceback (most recent call last):
  File "/usr/local/lib/python2.7/dist-packages/django/core/handlers/base.py", line 112, in get_response
    response = wrapped_callback(request, *callback_args, **callback_kwargs)
  File "/usr/local/lib/python2.7/dist-packages/django/bin/myste/opt/views.py", line 27, in opt_data
    s=json.dumps(p)
  File "/usr/lib/python2.7/json/__init__.py", line 243, in dumps
    return _default_encoder.encode(obj)
  File "/usr/lib/python2.7/json/encoder.py", line 207, in encode
    chunks = self.iterencode(o, _one_shot=True)
  File "/usr/lib/python2.7/json/encoder.py", line 270, in iterencode
    return _iterencode(o, 0)
  File "/usr/lib/python2.7/json/encoder.py", line 184, in default
    raise TypeError(repr(o) + " is not JSON serializable")
TypeError: datetime.datetime(2014, 7, 23, 14, 56, 25) is not JSON serializable
2014-07-23 07:55:28,333 [Thread-3:-1244660928] [django.request:224] [ERROR]- Internal Server Error: /test1/
Traceback (most recent call last):
  File "/usr/local/lib/python2.7/dist-packages/django/core/handlers/base.py", line 112, in get_response
    response = wrapped_callback(request, *callback_args, **callback_kwargs)
  File "/usr/local/lib/python2.7/dist-packages/django/bin/myste/opt/views.py", line 27, in opt_data
    s=json.dumps(p)
  File "/usr/lib/python2.7/json/__init__.py", line 243, in dumps
    return _default_encoder.encode(obj)
  File "/usr/lib/python2.7/json/encoder.py", line 207, in encode
    chunks = self.iterencode(o, _one_shot=True)
  File "/usr/lib/python2.7/json/encoder.py", line 270, in iterencode
    return _iterencode(o, 0)
  File "/usr/lib/python2.7/json/encoder.py", line 184, in default
    raise TypeError(repr(o) + " is not JSON serializable")
TypeError: datetime.datetime(2014, 7, 23, 14, 56, 25) is not JSON serializable
2014-07-23 07:55:55,771 [Thread-1:-1244660928] [django.request:224] [ERROR]- Internal Server Error: /test1/
Traceback (most recent call last):
  File "/usr/local/lib/python2.7/dist-packages/django/core/handlers/base.py", line 112, in get_response
    response = wrapped_callback(request, *callback_args, **callback_kwargs)
  File "/usr/local/lib/python2.7/dist-packages/django/bin/myste/opt/views.py", line 27, in opt_data
    s=json.dumps(p,cls=DateEncoder)
  File "/usr/lib/python2.7/json/__init__.py", line 250, in dumps
    sort_keys=sort_keys, **kw).encode(obj)
  File "/usr/lib/python2.7/json/encoder.py", line 207, in encode
    chunks = self.iterencode(o, _one_shot=True)
  File "/usr/lib/python2.7/json/encoder.py", line 270, in iterencode
    return _iterencode(o, 0)
  File "/usr/local/lib/python2.7/dist-packages/django/bin/myste/opt/views.py", line 15, in default
    if isinstance(obj,datetime):
NameError: global name 'datetime' is not defined
2014-07-23 07:56:22,975 [Thread-1:-1244660928] [django.request:224] [ERROR]- Internal Server Error: /test1/
Traceback (most recent call last):
  File "/usr/local/lib/python2.7/dist-packages/django/core/handlers/base.py", line 112, in get_response
    response = wrapped_callback(request, *callback_args, **callback_kwargs)
  File "/usr/local/lib/python2.7/dist-packages/django/bin/myste/opt/views.py", line 28, in opt_data
    s=json.dumps(p,cls=DateEncoder)
  File "/usr/lib/python2.7/json/__init__.py", line 250, in dumps
    sort_keys=sort_keys, **kw).encode(obj)
  File "/usr/lib/python2.7/json/encoder.py", line 207, in encode
    chunks = self.iterencode(o, _one_shot=True)
  File "/usr/lib/python2.7/json/encoder.py", line 270, in iterencode
    return _iterencode(o, 0)
  File "/usr/local/lib/python2.7/dist-packages/django/bin/myste/opt/views.py", line 16, in default
    if isinstance(obj,datetime):
TypeError: isinstance() arg 2 must be a class, type, or tuple of classes and types
2014-07-23 07:57:06,859 [Thread-3:-1244660928] [django.request:224] [ERROR]- Internal Server Error: /test1/
Traceback (most recent call last):
  File "/usr/local/lib/python2.7/dist-packages/django/core/handlers/base.py", line 112, in get_response
    response = wrapped_callback(request, *callback_args, **callback_kwargs)
  File "/usr/local/lib/python2.7/dist-packages/django/bin/myste/opt/views.py", line 28, in opt_data
    s=json.dumps(p,cls=DateEncoder)
  File "/usr/lib/python2.7/json/__init__.py", line 250, in dumps
    sort_keys=sort_keys, **kw).encode(obj)
  File "/usr/lib/python2.7/json/encoder.py", line 207, in encode
    chunks = self.iterencode(o, _one_shot=True)
  File "/usr/lib/python2.7/json/encoder.py", line 270, in iterencode
    return _iterencode(o, 0)
  File "/usr/local/lib/python2.7/dist-packages/django/bin/myste/opt/views.py", line 16, in default
    if isinstance(obj,datetime):
TypeError: isinstance() arg 2 must be a class, type, or tuple of classes and types
2014-07-23 07:59:31,640 [Thread-4:-1244660928] [django.request:224] [ERROR]- Internal Server Error: /test1/
Traceback (most recent call last):
  File "/usr/local/lib/python2.7/dist-packages/django/core/handlers/base.py", line 112, in get_response
    response = wrapped_callback(request, *callback_args, **callback_kwargs)
  File "/usr/local/lib/python2.7/dist-packages/django/bin/myste/opt/views.py", line 28, in opt_data
    s=json.dumps(p,cls=DateEncoder)
  File "/usr/lib/python2.7/json/__init__.py", line 250, in dumps
    sort_keys=sort_keys, **kw).encode(obj)
  File "/usr/lib/python2.7/json/encoder.py", line 207, in encode
    chunks = self.iterencode(o, _one_shot=True)
  File "/usr/lib/python2.7/json/encoder.py", line 270, in iterencode
    return _iterencode(o, 0)
  File "/usr/local/lib/python2.7/dist-packages/django/bin/myste/opt/views.py", line 16, in default
    if isinstance(obj,datetime):
TypeError: isinstance() arg 2 must be a class, type, or tuple of classes and types
2014-07-23 08:03:29,582 [Thread-1:-1245709504] [django.request:224] [ERROR]- Internal Server Error: /test1/
Traceback (most recent call last):
  File "/usr/local/lib/python2.7/dist-packages/django/core/handlers/base.py", line 112, in get_response
    response = wrapped_callback(request, *callback_args, **callback_kwargs)
  File "/usr/local/lib/python2.7/dist-packages/django/bin/myste/opt/views.py", line 28, in opt_data
    logger.debug("debugvvvvvvv")
NameError: global name 'logger' is not defined
2014-07-23 08:03:31,705 [Thread-3:-1245709504] [django.request:224] [ERROR]- Internal Server Error: /test1/
Traceback (most recent call last):
  File "/usr/local/lib/python2.7/dist-packages/django/core/handlers/base.py", line 112, in get_response
    response = wrapped_callback(request, *callback_args, **callback_kwargs)
  File "/usr/local/lib/python2.7/dist-packages/django/bin/myste/opt/views.py", line 28, in opt_data
    logger.debug("debugvvvvvvv")
NameError: global name 'logger' is not defined
2014-07-23 08:04:59,098 [Thread-1:-1244923072] [django.request:224] [ERROR]- Internal Server Error: /test1/
Traceback (most recent call last):
  File "/usr/local/lib/python2.7/dist-packages/django/core/handlers/base.py", line 112, in get_response
    response = wrapped_callback(request, *callback_args, **callback_kwargs)
  File "/usr/local/lib/python2.7/dist-packages/django/bin/myste/opt/views.py", line 35, in opt_data
    return render_to_response('test1.html',{'getsiteinfo':s})
NameError: global name 's' is not defined
2014-07-23 08:05:04,488 [Thread-3:-1244923072] [django.request:224] [ERROR]- Internal Server Error: /test1/
Traceback (most recent call last):
  File "/usr/local/lib/python2.7/dist-packages/django/core/handlers/base.py", line 112, in get_response
    response = wrapped_callback(request, *callback_args, **callback_kwargs)
  File "/usr/local/lib/python2.7/dist-packages/django/bin/myste/opt/views.py", line 35, in opt_data
    return render_to_response('test1.html',{'getsiteinfo':s})
NameError: global name 's' is not defined
2014-07-23 08:05:55,621 [Thread-4:-1244923072] [django.request:224] [ERROR]- Internal Server Error: /test1/
Traceback (most recent call last):
  File "/usr/local/lib/python2.7/dist-packages/django/core/handlers/base.py", line 112, in get_response
    response = wrapped_callback(request, *callback_args, **callback_kwargs)
  File "/usr/local/lib/python2.7/dist-packages/django/bin/myste/opt/views.py", line 35, in opt_data
    return render_to_response('test1.html',{'getsiteinfo':s})
NameError: global name 's' is not defined
2014-07-23 08:07:29,001 [Thread-1:-1245709504] [django.request:224] [ERROR]- Internal Server Error: /test1/
Traceback (most recent call last):
  File "/usr/local/lib/python2.7/dist-packages/django/core/handlers/base.py", line 112, in get_response
    response = wrapped_callback(request, *callback_args, **callback_kwargs)
  File "/usr/local/lib/python2.7/dist-packages/django/bin/myste/opt/views.py", line 28, in opt_data
    s=json.dumps(p,cls="DateEncoder")
  File "/usr/lib/python2.7/json/__init__.py", line 250, in dumps
    sort_keys=sort_keys, **kw).encode(obj)
TypeError: 'str' object is not callable
2014-07-23 08:33:39,743 [Thread-1:-1245709504] [django.request:224] [ERROR]- Internal Server Error: /test1/
Traceback (most recent call last):
  File "/usr/local/lib/python2.7/dist-packages/django/core/handlers/base.py", line 112, in get_response
    response = wrapped_callback(request, *callback_args, **callback_kwargs)
  File "/usr/local/lib/python2.7/dist-packages/django/bin/myste/opt/views.py", line 21, in opt_data
    mysql.updateMysql()
  File "/usr/local/lib/python2.7/dist-packages/django/bin/myste/opt/templates/mysql.py", line 71, in updateMysql
    excel2mysql(f)
  File "/usr/local/lib/python2.7/dist-packages/django/bin/myste/opt/templates/mysql.py", line 21, in excel2mysql
    wb=xlrd.open_workbook(fi,encoding_override="utf-8")
  File "/usr/local/lib/python2.7/dist-packages/xlrd/__init__.py", line 394, in open_workbook
    f = open(filename, "rb")
IOError: [Errno 2] No such file or directory: 'youhua_2014-07-23.xlsx'
2014-07-23 08:45:16,854 [Thread-1:-1245709504] [django.request:224] [ERROR]- Internal Server Error: /test1/
Traceback (most recent call last):
  File "/usr/local/lib/python2.7/dist-packages/django/core/handlers/base.py", line 112, in get_response
    response = wrapped_callback(request, *callback_args, **callback_kwargs)
  File "/usr/local/lib/python2.7/dist-packages/django/bin/myste/opt/views.py", line 21, in opt_data
    mysql.updateMysql()
  File "/usr/local/lib/python2.7/dist-packages/django/bin/myste/opt/templates/mysql.py", line 71, in updateMysql
    excel2mysql(f)
  File "/usr/local/lib/python2.7/dist-packages/django/bin/myste/opt/templates/mysql.py", line 21, in excel2mysql
    wb=xlrd.open_workbook(fi,encoding_override="utf-8")
  File "/usr/local/lib/python2.7/dist-packages/xlrd/__init__.py", line 394, in open_workbook
    f = open(filename, "rb")
IOError: [Errno 2] No such file or directory: 'youhua_2014-07-23.xlsx'
2014-07-23 08:45:36,984 [Thread-4:-1256195264] [django.request:224] [ERROR]- Internal Server Error: /test1/
Traceback (most recent call last):
  File "/usr/local/lib/python2.7/dist-packages/django/core/handlers/base.py", line 112, in get_response
    response = wrapped_callback(request, *callback_args, **callback_kwargs)
  File "/usr/local/lib/python2.7/dist-packages/django/bin/myste/opt/views.py", line 21, in opt_data
    mysql.updateMysql()
  File "/usr/local/lib/python2.7/dist-packages/django/bin/myste/opt/templates/mysql.py", line 71, in updateMysql
    excel2mysql(f)
  File "/usr/local/lib/python2.7/dist-packages/django/bin/myste/opt/templates/mysql.py", line 21, in excel2mysql
    wb=xlrd.open_workbook(fi,encoding_override="utf-8")
  File "/usr/local/lib/python2.7/dist-packages/xlrd/__init__.py", line 394, in open_workbook
    f = open(filename, "rb")
IOError: [Errno 2] No such file or directory: 'youhua_2014-07-23.xlsx'
2014-07-23 08:46:58,017 [Thread-5:-1256195264] [django.request:224] [ERROR]- Internal Server Error: /test1/
Traceback (most recent call last):
  File "/usr/local/lib/python2.7/dist-packages/django/core/handlers/base.py", line 112, in get_response
    response = wrapped_callback(request, *callback_args, **callback_kwargs)
  File "/usr/local/lib/python2.7/dist-packages/django/bin/myste/opt/views.py", line 21, in opt_data
    mysql.updateMysql()
  File "/usr/local/lib/python2.7/dist-packages/django/bin/myste/opt/templates/mysql.py", line 71, in updateMysql
    excel2mysql(f)
  File "/usr/local/lib/python2.7/dist-packages/django/bin/myste/opt/templates/mysql.py", line 21, in excel2mysql
    wb=xlrd.open_workbook(fi,encoding_override="utf-8")
  File "/usr/local/lib/python2.7/dist-packages/xlrd/__init__.py", line 394, in open_workbook
    f = open(filename, "rb")
IOError: [Errno 2] No such file or directory: 'youhua_2014-07-23.xlsx'
2014-07-23 08:47:53,296 [Thread-1:-1244660928] [django.request:224] [ERROR]- Internal Server Error: /test1/
Traceback (most recent call last):
  File "/usr/local/lib/python2.7/dist-packages/django/core/handlers/base.py", line 112, in get_response
    response = wrapped_callback(request, *callback_args, **callback_kwargs)
  File "/usr/local/lib/python2.7/dist-packages/django/bin/myste/opt/views.py", line 21, in opt_data
    mysql.updateMysql()
  File "/usr/local/lib/python2.7/dist-packages/django/bin/myste/opt/templates/mysql.py", line 71, in updateMysql
    excel2mysql('home/btc/data/changjiang/%s'%f)
  File "/usr/local/lib/python2.7/dist-packages/django/bin/myste/opt/templates/mysql.py", line 21, in excel2mysql
    wb=xlrd.open_workbook(fi,encoding_override="utf-8")
  File "/usr/local/lib/python2.7/dist-packages/xlrd/__init__.py", line 394, in open_workbook
    f = open(filename, "rb")
IOError: [Errno 2] No such file or directory: 'home/btc/data/changjiang/youhua_2014-07-23.xlsx'
2014-07-23 08:47:58,551 [Thread-3:-1244660928] [django.request:224] [ERROR]- Internal Server Error: /test1/
Traceback (most recent call last):
  File "/usr/local/lib/python2.7/dist-packages/django/core/handlers/base.py", line 112, in get_response
    response = wrapped_callback(request, *callback_args, **callback_kwargs)
  File "/usr/local/lib/python2.7/dist-packages/django/bin/myste/opt/views.py", line 21, in opt_data
    mysql.updateMysql()
  File "/usr/local/lib/python2.7/dist-packages/django/bin/myste/opt/templates/mysql.py", line 71, in updateMysql
    excel2mysql('home/btc/data/changjiang/%s'%f)
  File "/usr/local/lib/python2.7/dist-packages/django/bin/myste/opt/templates/mysql.py", line 21, in excel2mysql
    wb=xlrd.open_workbook(fi,encoding_override="utf-8")
  File "/usr/local/lib/python2.7/dist-packages/xlrd/__init__.py", line 394, in open_workbook
    f = open(filename, "rb")
IOError: [Errno 2] No such file or directory: 'home/btc/data/changjiang/youhua_2014-07-23.xlsx'
2014-07-23 09:06:59,760 [Thread-1:-1244660928] [django.request:224] [ERROR]- Internal Server Error: /test1/
Traceback (most recent call last):
  File "/usr/local/lib/python2.7/dist-packages/django/core/handlers/base.py", line 112, in get_response
    response = wrapped_callback(request, *callback_args, **callback_kwargs)
  File "/usr/local/lib/python2.7/dist-packages/django/bin/myste/opt/views.py", line 21, in opt_data
    mysql.updateMysql()
  File "/usr/local/lib/python2.7/dist-packages/django/bin/myste/opt/templates/mysql.py", line 72, in updateMysql
    excel2mysql('/home/btc/data/changjiang/%s'%f)
  File "/usr/local/lib/python2.7/dist-packages/django/bin/myste/opt/templates/mysql.py", line 16, in excel2mysql
    print flag1
NameError: global name 'flag1' is not defined
2014-07-23 10:00:31,090 [Thread-1:-1244714176] [django.request:224] [ERROR]- Internal Server Error: /test1/
Traceback (most recent call last):
  File "/usr/local/lib/python2.7/dist-packages/django/core/handlers/base.py", line 99, in get_response
    resolver_match = resolver.resolve(request.path_info)
  File "/usr/local/lib/python2.7/dist-packages/django/core/urlresolvers.py", line 339, in resolve
    sub_match = pattern.resolve(new_path)
  File "/usr/local/lib/python2.7/dist-packages/django/core/urlresolvers.py", line 223, in resolve
    return ResolverMatch(self.callback, args, kwargs, self.name)
  File "/usr/local/lib/python2.7/dist-packages/django/core/urlresolvers.py", line 230, in callback
    self._callback = get_callable(self._callback_str)
  File "/usr/local/lib/python2.7/dist-packages/django/utils/functional.py", line 32, in wrapper
    result = func(*args)
  File "/usr/local/lib/python2.7/dist-packages/django/core/urlresolvers.py", line 97, in get_callable
    mod = import_module(mod_name)
  File "/usr/local/lib/python2.7/dist-packages/django/utils/importlib.py", line 40, in import_module
    __import__(name)
  File "/usr/local/lib/python2.7/dist-packages/django/bin/myste/opt/views.py", line 11, in <module>
    from templates import mysql
  File "/usr/local/lib/python2.7/dist-packages/django/bin/myste/opt/templates/mysql.py", line 45
    if s[i][o][1] == :
                     ^
SyntaxError: invalid syntax
2014-07-24 00:53:50,717 [Thread-4:-1255146688] [django.request:143] [WARNING]- Not Found: /favicon.ico
2014-07-24 06:12:26,863 [Thread-4:-1256195264] [django.request:224] [ERROR]- Internal Server Error: /opt/
Traceback (most recent call last):
  File "/usr/local/lib/python2.7/dist-packages/django/core/handlers/base.py", line 112, in get_response
    response = wrapped_callback(request, *callback_args, **callback_kwargs)
  File "/usr/local/lib/python2.7/dist-packages/django/bin/myste/opt/views.py", line 40, in index
    return render_to_response('show.html',{'getsiteinfo':s})
  File "/usr/local/lib/python2.7/dist-packages/django/shortcuts/__init__.py", line 29, in render_to_response
    return HttpResponse(loader.render_to_string(*args, **kwargs), **httpresponse_kwargs)
  File "/usr/local/lib/python2.7/dist-packages/django/template/loader.py", line 162, in render_to_string
    t = get_template(template_name)
  File "/usr/local/lib/python2.7/dist-packages/django/template/loader.py", line 138, in get_template
    template, origin = find_template(template_name)
  File "/usr/local/lib/python2.7/dist-packages/django/template/loader.py", line 127, in find_template
    source, display_name = loader(name, dirs)
  File "/usr/local/lib/python2.7/dist-packages/django/template/loader.py", line 43, in __call__
    return self.load_template(template_name, template_dirs)
  File "/usr/local/lib/python2.7/dist-packages/django/template/loader.py", line 46, in load_template
    source, display_name = self.load_template_source(template_name, template_dirs)
  File "/usr/local/lib/python2.7/dist-packages/django/template/loaders/app_directories.py", line 60, in load_template_source
    return (fp.read().decode(settings.FILE_CHARSET), filepath)
  File "/usr/lib/python2.7/encodings/utf_8.py", line 16, in decode
    return codecs.utf_8_decode(input, errors, True)
UnicodeDecodeError: 'utf8' codec can't decode byte 0xd5 in position 161: invalid continuation byte
2014-07-24 06:14:36,427 [Thread-5:-1256195264] [django.request:224] [ERROR]- Internal Server Error: /opt/
Traceback (most recent call last):
  File "/usr/local/lib/python2.7/dist-packages/django/core/handlers/base.py", line 112, in get_response
    response = wrapped_callback(request, *callback_args, **callback_kwargs)
  File "/usr/local/lib/python2.7/dist-packages/django/bin/myste/opt/views.py", line 40, in index
    return render_to_response('show.html',{'getsiteinfo':s})
  File "/usr/local/lib/python2.7/dist-packages/django/shortcuts/__init__.py", line 29, in render_to_response
    return HttpResponse(loader.render_to_string(*args, **kwargs), **httpresponse_kwargs)
  File "/usr/local/lib/python2.7/dist-packages/django/template/loader.py", line 162, in render_to_string
    t = get_template(template_name)
  File "/usr/local/lib/python2.7/dist-packages/django/template/loader.py", line 138, in get_template
    template, origin = find_template(template_name)
  File "/usr/local/lib/python2.7/dist-packages/django/template/loader.py", line 127, in find_template
    source, display_name = loader(name, dirs)
  File "/usr/local/lib/python2.7/dist-packages/django/template/loader.py", line 43, in __call__
    return self.load_template(template_name, template_dirs)
  File "/usr/local/lib/python2.7/dist-packages/django/template/loader.py", line 46, in load_template
    source, display_name = self.load_template_source(template_name, template_dirs)
  File "/usr/local/lib/python2.7/dist-packages/django/template/loaders/app_directories.py", line 60, in load_template_source
    return (fp.read().decode(settings.FILE_CHARSET), filepath)
  File "/usr/lib/python2.7/encodings/utf_8.py", line 16, in decode
    return codecs.utf_8_decode(input, errors, True)
UnicodeDecodeError: 'utf8' codec can't decode byte 0xce in position 250: invalid continuation byte
2014-07-24 06:14:40,195 [Thread-6:-1256195264] [django.request:224] [ERROR]- Internal Server Error: /opt/
Traceback (most recent call last):
  File "/usr/local/lib/python2.7/dist-packages/django/core/handlers/base.py", line 112, in get_response
    response = wrapped_callback(request, *callback_args, **callback_kwargs)
  File "/usr/local/lib/python2.7/dist-packages/django/bin/myste/opt/views.py", line 40, in index
    return render_to_response('show.html',{'getsiteinfo':s})
  File "/usr/local/lib/python2.7/dist-packages/django/shortcuts/__init__.py", line 29, in render_to_response
    return HttpResponse(loader.render_to_string(*args, **kwargs), **httpresponse_kwargs)
  File "/usr/local/lib/python2.7/dist-packages/django/template/loader.py", line 162, in render_to_string
    t = get_template(template_name)
  File "/usr/local/lib/python2.7/dist-packages/django/template/loader.py", line 138, in get_template
    template, origin = find_template(template_name)
  File "/usr/local/lib/python2.7/dist-packages/django/template/loader.py", line 127, in find_template
    source, display_name = loader(name, dirs)
  File "/usr/local/lib/python2.7/dist-packages/django/template/loader.py", line 43, in __call__
    return self.load_template(template_name, template_dirs)
  File "/usr/local/lib/python2.7/dist-packages/django/template/loader.py", line 46, in load_template
    source, display_name = self.load_template_source(template_name, template_dirs)
  File "/usr/local/lib/python2.7/dist-packages/django/template/loaders/app_directories.py", line 60, in load_template_source
    return (fp.read().decode(settings.FILE_CHARSET), filepath)
  File "/usr/lib/python2.7/encodings/utf_8.py", line 16, in decode
    return codecs.utf_8_decode(input, errors, True)
UnicodeDecodeError: 'utf8' codec can't decode byte 0xce in position 250: invalid continuation byte
2014-07-24 06:17:32,950 [Thread-7:-1256195264] [django.request:224] [ERROR]- Internal Server Error: /opt/
Traceback (most recent call last):
  File "/usr/local/lib/python2.7/dist-packages/django/core/handlers/base.py", line 112, in get_response
    response = wrapped_callback(request, *callback_args, **callback_kwargs)
  File "/usr/local/lib/python2.7/dist-packages/django/bin/myste/opt/views.py", line 40, in index
    return render_to_response('show.html',{'getsiteinfo':s})
  File "/usr/local/lib/python2.7/dist-packages/django/shortcuts/__init__.py", line 29, in render_to_response
    return HttpResponse(loader.render_to_string(*args, **kwargs), **httpresponse_kwargs)
  File "/usr/local/lib/python2.7/dist-packages/django/template/loader.py", line 162, in render_to_string
    t = get_template(template_name)
  File "/usr/local/lib/python2.7/dist-packages/django/template/loader.py", line 138, in get_template
    template, origin = find_template(template_name)
  File "/usr/local/lib/python2.7/dist-packages/django/template/loader.py", line 127, in find_template
    source, display_name = loader(name, dirs)
  File "/usr/local/lib/python2.7/dist-packages/django/template/loader.py", line 43, in __call__
    return self.load_template(template_name, template_dirs)
  File "/usr/local/lib/python2.7/dist-packages/django/template/loader.py", line 46, in load_template
    source, display_name = self.load_template_source(template_name, template_dirs)
  File "/usr/local/lib/python2.7/dist-packages/django/template/loaders/app_directories.py", line 60, in load_template_source
    return (fp.read().decode(settings.FILE_CHARSET), filepath)
  File "/usr/lib/python2.7/encodings/utf_8.py", line 16, in decode
    return codecs.utf_8_decode(input, errors, True)
UnicodeDecodeError: 'utf8' codec can't decode byte 0xce in position 250: invalid continuation byte
2014-07-24 06:18:27,224 [Thread-8:-1256195264] [django.request:224] [ERROR]- Internal Server Error: /opt/
Traceback (most recent call last):
  File "/usr/local/lib/python2.7/dist-packages/django/core/handlers/base.py", line 112, in get_response
    response = wrapped_callback(request, *callback_args, **callback_kwargs)
  File "/usr/local/lib/python2.7/dist-packages/django/bin/myste/opt/views.py", line 40, in index
    return render_to_response('show.html',{'getsiteinfo':s})
  File "/usr/local/lib/python2.7/dist-packages/django/shortcuts/__init__.py", line 29, in render_to_response
    return HttpResponse(loader.render_to_string(*args, **kwargs), **httpresponse_kwargs)
  File "/usr/local/lib/python2.7/dist-packages/django/template/loader.py", line 162, in render_to_string
    t = get_template(template_name)
  File "/usr/local/lib/python2.7/dist-packages/django/template/loader.py", line 138, in get_template
    template, origin = find_template(template_name)
  File "/usr/local/lib/python2.7/dist-packages/django/template/loader.py", line 127, in find_template
    source, display_name = loader(name, dirs)
  File "/usr/local/lib/python2.7/dist-packages/django/template/loader.py", line 43, in __call__
    return self.load_template(template_name, template_dirs)
  File "/usr/local/lib/python2.7/dist-packages/django/template/loader.py", line 46, in load_template
    source, display_name = self.load_template_source(template_name, template_dirs)
  File "/usr/local/lib/python2.7/dist-packages/django/template/loaders/app_directories.py", line 60, in load_template_source
    return (fp.read().decode(settings.FILE_CHARSET), filepath)
  File "/usr/lib/python2.7/encodings/utf_8.py", line 16, in decode
    return codecs.utf_8_decode(input, errors, True)
UnicodeDecodeError: 'utf8' codec can't decode byte 0xce in position 250: invalid continuation byte
2014-07-24 06:27:27,331 [Thread-10:-1256195264] [django.request:143] [WARNING]- Not Found: /opt/js/jquery.js
2014-07-24 06:31:08,261 [Thread-12:-1256195264] [django.request:143] [WARNING]- Not Found: /opt/js/jquery.js
2014-07-24 06:31:09,354 [Thread-14:-1256195264] [django.request:143] [WARNING]- Not Found: /opt/js/jquery.js
2014-07-24 06:45:14,568 [Thread-16:-1245709504] [django.request:143] [WARNING]- Not Found: /jquery.js
2014-07-24 08:01:43,651 [Thread-71:-1266681024] [django.request:143] [WARNING]- Not Found: /favicon.ico
2014-07-24 08:48:29,213 [Thread-6:-1256195264] [django.request:143] [WARNING]- Not Found: /ajax_deal/
2014-07-24 08:48:30,478 [Thread-7:-1256195264] [django.request:143] [WARNING]- Not Found: /ajax_deal/
2014-07-24 08:48:31,219 [Thread-8:-1256195264] [django.request:143] [WARNING]- Not Found: /ajax_deal/
2014-07-24 08:48:31,961 [Thread-9:-1256195264] [django.request:143] [WARNING]- Not Found: /ajax_deal/
2014-07-24 08:48:32,204 [Thread-10:-1256195264] [django.request:143] [WARNING]- Not Found: /ajax_deal/
2014-07-24 08:48:32,975 [Thread-11:-1256195264] [django.request:143] [WARNING]- Not Found: /ajax_deal/
2014-07-24 08:48:33,229 [Thread-12:-1256195264] [django.request:143] [WARNING]- Not Found: /ajax_deal/
2014-07-24 08:48:33,825 [Thread-13:-1256195264] [django.request:143] [WARNING]- Not Found: /ajax_deal/
2014-07-24 08:48:34,018 [Thread-14:-1256195264] [django.request:143] [WARNING]- Not Found: /ajax_deal/
2014-07-24 08:48:34,495 [Thread-15:-1256195264] [django.request:143] [WARNING]- Not Found: /ajax_deal/
2014-07-24 08:55:01,362 [Thread-9:-1275073728] [django.request:224] [ERROR]- Internal Server Error: /ajax_deal/
Traceback (most recent call last):
  File "/usr/local/lib/python2.7/dist-packages/django/core/handlers/base.py", line 112, in get_response
    response = wrapped_callback(request, *callback_args, **callback_kwargs)
  File "/usr/local/lib/python2.7/dist-packages/django/bin/myste/opt/views.py", line 42, in ajax_deal
    return HttpRespinse("hello")
NameError: global name 'HttpRespinse' is not defined
2014-07-24 08:56:56,214 [Thread-3:-1245709504] [django.request:99] [WARNING]- Forbidden (CSRF token missing or incorrect.): /ajax_deal/
2014-07-24 08:56:57,127 [Thread-4:-1245709504] [django.request:99] [WARNING]- Forbidden (CSRF token missing or incorrect.): /ajax_deal/
2014-07-24 08:56:57,407 [Thread-5:-1245709504] [django.request:99] [WARNING]- Forbidden (CSRF token missing or incorrect.): /ajax_deal/
2014-07-24 08:56:57,854 [Thread-6:-1245709504] [django.request:99] [WARNING]- Forbidden (CSRF token missing or incorrect.): /ajax_deal/
2014-07-24 08:56:58,060 [Thread-7:-1245709504] [django.request:99] [WARNING]- Forbidden (CSRF token missing or incorrect.): /ajax_deal/
2014-07-24 09:46:06,071 [Thread-1:-1245709504] [django.request:224] [ERROR]- Internal Server Error: /opt/
Traceback (most recent call last):
  File "/usr/local/lib/python2.7/dist-packages/django/core/handlers/base.py", line 112, in get_response
    response = wrapped_callback(request, *callback_args, **callback_kwargs)
  File "/usr/local/lib/python2.7/dist-packages/django/bin/myste/opt/views.py", line 46, in index
    return render_to_response('ajax.html',{'getsiteinfo':s})
  File "/usr/local/lib/python2.7/dist-packages/django/shortcuts/__init__.py", line 29, in render_to_response
    return HttpResponse(loader.render_to_string(*args, **kwargs), **httpresponse_kwargs)
  File "/usr/local/lib/python2.7/dist-packages/django/template/loader.py", line 162, in render_to_string
    t = get_template(template_name)
  File "/usr/local/lib/python2.7/dist-packages/django/template/loader.py", line 138, in get_template
    template, origin = find_template(template_name)
  File "/usr/local/lib/python2.7/dist-packages/django/template/loader.py", line 131, in find_template
    raise TemplateDoesNotExist(name)
TemplateDoesNotExist: ajax.html
2014-07-25 01:18:50,302 [Thread-4:-1255146688] [django.request:143] [WARNING]- Not Found: /favicon.ico
2014-07-25 01:41:24,594 [Thread-3:-1244923072] [django.request:143] [WARNING]- Not Found: /jquery/test1.txt
2014-07-25 01:41:25,237 [Thread-4:-1244923072] [django.request:143] [WARNING]- Not Found: /jquery/test1.txt
2014-07-25 01:41:25,457 [Thread-5:-1244923072] [django.request:143] [WARNING]- Not Found: /jquery/test1.txt
2014-07-25 01:42:21,743 [Thread-5:-1255146688] [django.request:143] [WARNING]- Not Found: /jquery/test1.txt
2014-07-25 01:42:22,273 [Thread-6:-1255146688] [django.request:143] [WARNING]- Not Found: /jquery/test1.txt
2014-07-25 01:42:22,503 [Thread-7:-1255146688] [django.request:143] [WARNING]- Not Found: /jquery/test1.txt
2014-07-25 01:42:22,705 [Thread-8:-1255146688] [django.request:143] [WARNING]- Not Found: /jquery/test1.txt
2014-07-25 01:42:22,896 [Thread-9:-1255146688] [django.request:143] [WARNING]- Not Found: /jquery/test1.txt
2014-07-25 01:42:23,111 [Thread-10:-1255146688] [django.request:143] [WARNING]- Not Found: /jquery/test1.txt
2014-07-25 01:42:35,244 [Thread-11:-1255146688] [django.request:143] [WARNING]- Not Found: /jquery/test1.txt
2014-07-25 01:42:35,832 [Thread-12:-1255146688] [django.request:143] [WARNING]- Not Found: /jquery/test1.txt
2014-07-25 01:42:36,113 [Thread-13:-1255146688] [django.request:143] [WARNING]- Not Found: /jquery/test1.txt
2014-07-25 01:42:36,665 [Thread-14:-1255146688] [django.request:143] [WARNING]- Not Found: /jquery/test1.txt
2014-07-25 01:42:57,887 [Thread-17:-1255146688] [django.request:143] [WARNING]- Not Found: /jquery/test1.txt
2014-07-25 01:42:58,734 [Thread-18:-1255146688] [django.request:143] [WARNING]- Not Found: /jquery/test1.txt
2014-07-25 01:42:59,267 [Thread-19:-1255146688] [django.request:143] [WARNING]- Not Found: /jquery/test1.txt
2014-07-25 01:43:18,463 [Thread-21:-1255146688] [django.request:143] [WARNING]- Not Found: /jquery/test1.txt
2014-07-25 01:44:53,162 [Thread-23:-1244660928] [django.request:143] [WARNING]- Not Found: /opt/getsiteinfo
2014-07-25 01:50:27,698 [Thread-27:-1282417856] [django.request:143] [WARNING]- Not Found: /opt/getsiteinfo
2014-07-25 01:54:19,144 [Thread-29:-1274025152] [django.request:143] [WARNING]- Not Found: /index/
2014-07-25 01:54:20,305 [Thread-30:-1265632448] [django.request:143] [WARNING]- Not Found: /index/
2014-07-25 01:54:27,284 [Thread-33:-1244660928] [django.request:143] [WARNING]- Not Found: /index/
2014-07-25 02:08:30,206 [Thread-51:-1274025152] [django.request:143] [WARNING]- Not Found: /index/
2014-07-25 02:08:36,098 [Thread-53:-1244660928] [django.request:143] [WARNING]- Not Found: /index/
2014-07-25 06:15:36,733 [Thread-1:-1244660928] [django.request:224] [ERROR]- Internal Server Error: /opt/
Traceback (most recent call last):
  File "/usr/local/lib/python2.7/dist-packages/django/core/handlers/base.py", line 99, in get_response
    resolver_match = resolver.resolve(request.path_info)
  File "/usr/local/lib/python2.7/dist-packages/django/core/urlresolvers.py", line 339, in resolve
    sub_match = pattern.resolve(new_path)
  File "/usr/local/lib/python2.7/dist-packages/django/core/urlresolvers.py", line 223, in resolve
    return ResolverMatch(self.callback, args, kwargs, self.name)
  File "/usr/local/lib/python2.7/dist-packages/django/core/urlresolvers.py", line 230, in callback
    self._callback = get_callable(self._callback_str)
  File "/usr/local/lib/python2.7/dist-packages/django/utils/functional.py", line 32, in wrapper
    result = func(*args)
  File "/usr/local/lib/python2.7/dist-packages/django/core/urlresolvers.py", line 97, in get_callable
    mod = import_module(mod_name)
  File "/usr/local/lib/python2.7/dist-packages/django/utils/importlib.py", line 40, in import_module
    __import__(name)
  File "/usr/local/lib/python2.7/dist-packages/django/bin/myste/opt/views.py", line 39
    timeOpt=request.POST['timeOpt'])
                                   ^
SyntaxError: invalid syntax
2014-07-25 06:18:26,745 [Thread-4:-1255146688] [django.request:224] [ERROR]- Internal Server Error: /opt/
Traceback (most recent call last):
  File "/usr/local/lib/python2.7/dist-packages/django/core/handlers/base.py", line 99, in get_response
    resolver_match = resolver.resolve(request.path_info)
  File "/usr/local/lib/python2.7/dist-packages/django/core/urlresolvers.py", line 339, in resolve
    sub_match = pattern.resolve(new_path)
  File "/usr/local/lib/python2.7/dist-packages/django/core/urlresolvers.py", line 223, in resolve
    return ResolverMatch(self.callback, args, kwargs, self.name)
  File "/usr/local/lib/python2.7/dist-packages/django/core/urlresolvers.py", line 230, in callback
    self._callback = get_callable(self._callback_str)
  File "/usr/local/lib/python2.7/dist-packages/django/utils/functional.py", line 32, in wrapper
    result = func(*args)
  File "/usr/local/lib/python2.7/dist-packages/django/core/urlresolvers.py", line 97, in get_callable
    mod = import_module(mod_name)
  File "/usr/local/lib/python2.7/dist-packages/django/utils/importlib.py", line 40, in import_module
    __import__(name)
  File "/usr/local/lib/python2.7/dist-packages/django/bin/myste/opt/views.py", line 21
    timeOpt=request.POST['timeOpt'])
                                   ^
SyntaxError: invalid syntax
2014-07-25 06:20:00,721 [Thread-5:-1255146688] [django.request:224] [ERROR]- Internal Server Error: /opt/
Traceback (most recent call last):
  File "/usr/local/lib/python2.7/dist-packages/django/core/handlers/base.py", line 99, in get_response
    resolver_match = resolver.resolve(request.path_info)
  File "/usr/local/lib/python2.7/dist-packages/django/core/urlresolvers.py", line 339, in resolve
    sub_match = pattern.resolve(new_path)
  File "/usr/local/lib/python2.7/dist-packages/django/core/urlresolvers.py", line 223, in resolve
    return ResolverMatch(self.callback, args, kwargs, self.name)
  File "/usr/local/lib/python2.7/dist-packages/django/core/urlresolvers.py", line 230, in callback
    self._callback = get_callable(self._callback_str)
  File "/usr/local/lib/python2.7/dist-packages/django/utils/functional.py", line 32, in wrapper
    result = func(*args)
  File "/usr/local/lib/python2.7/dist-packages/django/core/urlresolvers.py", line 97, in get_callable
    mod = import_module(mod_name)
  File "/usr/local/lib/python2.7/dist-packages/django/utils/importlib.py", line 40, in import_module
    __import__(name)
  File "/usr/local/lib/python2.7/dist-packages/django/bin/myste/opt/views.py", line 38
    timeOpt=request.POST['timeOpt'])
                                   ^
SyntaxError: invalid syntax
2014-07-25 06:28:11,545 [Thread-6:-1255146688] [django.request:224] [ERROR]- Internal Server Error: /opt/
Traceback (most recent call last):
  File "/usr/local/lib/python2.7/dist-packages/django/core/handlers/base.py", line 99, in get_response
    resolver_match = resolver.resolve(request.path_info)
  File "/usr/local/lib/python2.7/dist-packages/django/core/urlresolvers.py", line 339, in resolve
    sub_match = pattern.resolve(new_path)
  File "/usr/local/lib/python2.7/dist-packages/django/core/urlresolvers.py", line 223, in resolve
    return ResolverMatch(self.callback, args, kwargs, self.name)
  File "/usr/local/lib/python2.7/dist-packages/django/core/urlresolvers.py", line 230, in callback
    self._callback = get_callable(self._callback_str)
  File "/usr/local/lib/python2.7/dist-packages/django/utils/functional.py", line 32, in wrapper
    result = func(*args)
  File "/usr/local/lib/python2.7/dist-packages/django/core/urlresolvers.py", line 97, in get_callable
    mod = import_module(mod_name)
  File "/usr/local/lib/python2.7/dist-packages/django/utils/importlib.py", line 40, in import_module
    __import__(name)
  File "/usr/local/lib/python2.7/dist-packages/django/bin/myste/opt/views.py", line 38
    timeOpt=request.POST['timeOpt'])
                                   ^
SyntaxError: invalid syntax
2014-07-25 06:36:35,745 [Thread-8:-1255146688] [django.request:99] [WARNING]- Forbidden (CSRF token missing or incorrect.): /test1/
2014-07-25 06:37:58,417 [Thread-3:-1244923072] [django.request:99] [WARNING]- Forbidden (CSRF token missing or incorrect.): /test1/
2014-07-25 06:39:04,643 [Thread-5:-1255408832] [django.request:99] [WARNING]- Forbidden (CSRF token missing or incorrect.): /test1/
2014-07-25 06:39:20,792 [Thread-8:-1255408832] [django.request:99] [WARNING]- Forbidden (CSRF token missing or incorrect.): /test1/
2014-07-25 06:39:42,532 [Thread-11:-1255408832] [django.request:99] [WARNING]- Forbidden (CSRF token missing or incorrect.): /test1/
2014-07-25 06:40:32,206 [Thread-3:-1255146688] [django.request:99] [WARNING]- Forbidden (CSRF token missing or incorrect.): /test1/
2014-07-25 06:42:25,203 [Thread-3:-1256195264] [django.request:99] [WARNING]- Forbidden (CSRF token missing or incorrect.): /test1/
2014-07-25 06:42:55,053 [Thread-6:-1266681024] [django.request:99] [WARNING]- Forbidden (CSRF token missing or incorrect.): /test1/
2014-07-25 06:43:51,307 [Thread-9:-1266681024] [django.request:99] [WARNING]- Forbidden (CSRF token missing or incorrect.): /test1/
2014-07-25 06:47:13,607 [Thread-11:-1266681024] [django.request:99] [WARNING]- Forbidden (CSRF token missing or incorrect.): /test1/
2014-07-25 06:51:30,451 [Thread-12:-1266681024] [django.request:99] [WARNING]- Forbidden (CSRF token missing or incorrect.): /test1/
2014-07-25 06:51:42,395 [Thread-16:-1256195264] [django.request:99] [WARNING]- Forbidden (CSRF token missing or incorrect.): /test1/
2014-07-25 07:04:16,353 [Thread-1:-1245709504] [django.request:224] [ERROR]- Internal Server Error: /opt/
Traceback (most recent call last):
  File "/usr/local/lib/python2.7/dist-packages/django/core/handlers/base.py", line 99, in get_response
    resolver_match = resolver.resolve(request.path_info)
  File "/usr/local/lib/python2.7/dist-packages/django/core/urlresolvers.py", line 339, in resolve
    sub_match = pattern.resolve(new_path)
  File "/usr/local/lib/python2.7/dist-packages/django/core/urlresolvers.py", line 223, in resolve
    return ResolverMatch(self.callback, args, kwargs, self.name)
  File "/usr/local/lib/python2.7/dist-packages/django/core/urlresolvers.py", line 230, in callback
    self._callback = get_callable(self._callback_str)
  File "/usr/local/lib/python2.7/dist-packages/django/utils/functional.py", line 32, in wrapper
    result = func(*args)
  File "/usr/local/lib/python2.7/dist-packages/django/core/urlresolvers.py", line 97, in get_callable
    mod = import_module(mod_name)
  File "/usr/local/lib/python2.7/dist-packages/django/utils/importlib.py", line 40, in import_module
    __import__(name)
  File "/usr/local/lib/python2.7/dist-packages/django/bin/myste/opt/views.py", line 37, in <module>
    @csrf_protect
NameError: name 'csrf_protect' is not defined
2014-07-25 07:06:04,756 [Thread-5:-1266681024] [django.request:224] [ERROR]- Internal Server Error: /opt/
Traceback (most recent call last):
  File "/usr/local/lib/python2.7/dist-packages/django/core/handlers/base.py", line 99, in get_response
    resolver_match = resolver.resolve(request.path_info)
  File "/usr/local/lib/python2.7/dist-packages/django/core/urlresolvers.py", line 339, in resolve
    sub_match = pattern.resolve(new_path)
  File "/usr/local/lib/python2.7/dist-packages/django/core/urlresolvers.py", line 223, in resolve
    return ResolverMatch(self.callback, args, kwargs, self.name)
  File "/usr/local/lib/python2.7/dist-packages/django/core/urlresolvers.py", line 230, in callback
    self._callback = get_callable(self._callback_str)
  File "/usr/local/lib/python2.7/dist-packages/django/utils/functional.py", line 32, in wrapper
    result = func(*args)
  File "/usr/local/lib/python2.7/dist-packages/django/core/urlresolvers.py", line 97, in get_callable
    mod = import_module(mod_name)
  File "/usr/local/lib/python2.7/dist-packages/django/utils/importlib.py", line 40, in import_module
    __import__(name)
  File "/usr/local/lib/python2.7/dist-packages/django/bin/myste/opt/views.py", line 37, in <module>
    @csrf_protect
NameError: name 'csrf_protect' is not defined
2014-07-25 07:06:30,029 [Thread-9:-1245709504] [django.request:99] [WARNING]- Forbidden (CSRF token missing or incorrect.): /test1/
2014-07-25 07:06:41,756 [Thread-13:-1256195264] [django.request:99] [WARNING]- Forbidden (CSRF token missing or incorrect.): /test1/
2014-07-25 07:08:42,401 [Thread-3:-1256195264] [django.request:99] [WARNING]- Forbidden (CSRF token missing or incorrect.): /test1/
2014-07-25 07:08:49,891 [Thread-6:-1266681024] [django.request:99] [WARNING]- Forbidden (CSRF token missing or incorrect.): /test1/
2014-07-25 07:09:18,713 [Thread-4:-1265632448] [django.request:99] [WARNING]- Forbidden (CSRF token missing or incorrect.): /test1/
2014-07-25 07:10:13,604 [Thread-1:-1245709504] [django.request:224] [ERROR]- Internal Server Error: /opt/
Traceback (most recent call last):
  File "/usr/local/lib/python2.7/dist-packages/django/core/handlers/base.py", line 99, in get_response
    resolver_match = resolver.resolve(request.path_info)
  File "/usr/local/lib/python2.7/dist-packages/django/core/urlresolvers.py", line 339, in resolve
    sub_match = pattern.resolve(new_path)
  File "/usr/local/lib/python2.7/dist-packages/django/core/urlresolvers.py", line 223, in resolve
    return ResolverMatch(self.callback, args, kwargs, self.name)
  File "/usr/local/lib/python2.7/dist-packages/django/core/urlresolvers.py", line 230, in callback
    self._callback = get_callable(self._callback_str)
  File "/usr/local/lib/python2.7/dist-packages/django/utils/functional.py", line 32, in wrapper
    result = func(*args)
  File "/usr/local/lib/python2.7/dist-packages/django/core/urlresolvers.py", line 97, in get_callable
    mod = import_module(mod_name)
  File "/usr/local/lib/python2.7/dist-packages/django/utils/importlib.py", line 40, in import_module
    __import__(name)
  File "/usr/local/lib/python2.7/dist-packages/django/bin/myste/opt/views.py", line 38, in <module>
    @csrf_protect
NameError: name 'csrf_protect' is not defined
2014-07-25 07:10:34,300 [Thread-7:-1266681024] [django.request:99] [WARNING]- Forbidden (CSRF token missing or incorrect.): /test1/
2014-07-25 07:14:17,886 [Thread-10:-1266681024] [django.request:99] [WARNING]- Forbidden (CSRF token missing or incorrect.): /test1/
2014-07-25 07:14:24,917 [Thread-13:-1275073728] [django.request:99] [WARNING]- Forbidden (CSRF token missing or incorrect.): /test1/
2014-07-25 07:15:49,253 [Thread-16:-1275073728] [django.request:143] [WARNING]- Not Found: /favicon.ico
2014-07-25 07:15:51,717 [Thread-17:-1275073728] [django.request:99] [WARNING]- Forbidden (CSRF cookie not set.): /test1/
2014-07-25 07:17:16,367 [Thread-1:-1245709504] [django.request:224] [ERROR]- Internal Server Error: /opt/
Traceback (most recent call last):
  File "/usr/local/lib/python2.7/dist-packages/django/core/handlers/base.py", line 99, in get_response
    resolver_match = resolver.resolve(request.path_info)
  File "/usr/local/lib/python2.7/dist-packages/django/core/urlresolvers.py", line 339, in resolve
    sub_match = pattern.resolve(new_path)
  File "/usr/local/lib/python2.7/dist-packages/django/core/urlresolvers.py", line 223, in resolve
    return ResolverMatch(self.callback, args, kwargs, self.name)
  File "/usr/local/lib/python2.7/dist-packages/django/core/urlresolvers.py", line 230, in callback
    self._callback = get_callable(self._callback_str)
  File "/usr/local/lib/python2.7/dist-packages/django/utils/functional.py", line 32, in wrapper
    result = func(*args)
  File "/usr/local/lib/python2.7/dist-packages/django/core/urlresolvers.py", line 97, in get_callable
    mod = import_module(mod_name)
  File "/usr/local/lib/python2.7/dist-packages/django/utils/importlib.py", line 40, in import_module
    __import__(name)
  File "/usr/local/lib/python2.7/dist-packages/django/bin/myste/opt/views.py", line 38, in <module>
    @csrf_exempt
NameError: name 'csrf_exempt' is not defined
2014-07-25 07:17:53,793 [Thread-6:-1266681024] [django.request:224] [ERROR]- Internal Server Error: /opt/
Traceback (most recent call last):
  File "/usr/local/lib/python2.7/dist-packages/django/core/handlers/base.py", line 99, in get_response
    resolver_match = resolver.resolve(request.path_info)
  File "/usr/local/lib/python2.7/dist-packages/django/core/urlresolvers.py", line 339, in resolve
    sub_match = pattern.resolve(new_path)
  File "/usr/local/lib/python2.7/dist-packages/django/core/urlresolvers.py", line 223, in resolve
    return ResolverMatch(self.callback, args, kwargs, self.name)
  File "/usr/local/lib/python2.7/dist-packages/django/core/urlresolvers.py", line 230, in callback
    self._callback = get_callable(self._callback_str)
  File "/usr/local/lib/python2.7/dist-packages/django/utils/functional.py", line 32, in wrapper
    result = func(*args)
  File "/usr/local/lib/python2.7/dist-packages/django/core/urlresolvers.py", line 97, in get_callable
    mod = import_module(mod_name)
  File "/usr/local/lib/python2.7/dist-packages/django/utils/importlib.py", line 40, in import_module
    __import__(name)
  File "/usr/local/lib/python2.7/dist-packages/django/bin/myste/opt/views.py", line 38, in <module>
    @csrf_exempt
NameError: name 'csrf_exempt' is not defined
2014-07-25 07:18:09,366 [Thread-9:-1256195264] [django.request:224] [ERROR]- Internal Server Error: /opt/
Traceback (most recent call last):
  File "/usr/local/lib/python2.7/dist-packages/django/core/handlers/base.py", line 112, in get_response
    response = wrapped_callback(request, *callback_args, **callback_kwargs)
  File "/usr/local/lib/python2.7/dist-packages/django/bin/myste/opt/views.py", line 41, in opt
    logger.info("%s"%timeOpt)
NameError: global name 'logger' is not defined
2014-07-25 07:21:53,110 [Thread-1:-1245709504] [django.request:224] [ERROR]- Internal Server Error: /opt/
Traceback (most recent call last):
  File "/usr/local/lib/python2.7/dist-packages/django/core/handlers/base.py", line 112, in get_response
    response = wrapped_callback(request, *callback_args, **callback_kwargs)
  File "/usr/local/lib/python2.7/dist-packages/django/bin/myste/opt/views.py", line 39, in opt
    timeOpt=request.POST['timeOpt']
  File "/usr/local/lib/python2.7/dist-packages/django/utils/datastructures.py", line 301, in __getitem__
    raise MultiValueDictKeyError(repr(key))
MultiValueDictKeyError: "'timeOpt'"
2014-07-25 07:24:39,657 [Thread-3:-1245709504] [django.request:99] [WARNING]- Forbidden (CSRF token missing or incorrect.): /test1/
2014-07-25 07:31:33,843 [Thread-6:-1256195264] [django.request:99] [WARNING]- Forbidden (CSRF token missing or incorrect.): /test1/
2014-07-25 07:31:51,648 [Thread-10:-1256195264] [django.request:99] [WARNING]- Forbidden (CSRF token missing or incorrect.): /test1/
2014-07-25 07:43:40,489 [Thread-3:-1245709504] [django.request:99] [WARNING]- Forbidden (CSRF token missing or incorrect.): /test1/
2014-07-25 09:19:55,183 [Thread-15:-1244660928] [django.request:143] [WARNING]- Not Found: /opt/jquery-1.3.2.js
2014-07-25 09:19:55,243 [Thread-16:-1255146688] [django.request:143] [WARNING]- Not Found: /opt/jquery.date_input.js
2014-07-25 09:19:55,249 [Thread-17:-1244660928] [django.request:143] [WARNING]- Not Found: /opt/date_input.css
2014-07-25 09:20:30,838 [Thread-27:-1244660928] [django.request:143] [WARNING]- Not Found: /opt/jquery-1.3.2.js
2014-07-25 09:20:30,867 [Thread-28:-1265632448] [django.request:143] [WARNING]- Not Found: /opt/jquery.date_input.js
2014-07-25 09:20:30,872 [Thread-29:-1274025152] [django.request:143] [WARNING]- Not Found: /opt/date_input.css
2014-07-25 09:20:35,673 [Thread-31:-1274025152] [django.request:143] [WARNING]- Not Found: /opt/jquery-1.3.2.js
2014-07-25 09:20:35,703 [Thread-32:-1274025152] [django.request:143] [WARNING]- Not Found: /opt/jquery.date_input.js
2014-07-25 09:20:35,712 [Thread-33:-1265632448] [django.request:143] [WARNING]- Not Found: /opt/date_input.css
2014-07-26 01:02:03,383 [Thread-4:-1265632448] [django.request:143] [WARNING]- Not Found: /favicon.ico
2014-07-26 07:44:14,288 [Thread-11:-1265632448] [django.request:224] [ERROR]- Internal Server Error: /test1/
Traceback (most recent call last):
  File "/usr/local/lib/python2.7/dist-packages/django/core/handlers/base.py", line 112, in get_response
    response = wrapped_callback(request, *callback_args, **callback_kwargs)
  File "/usr/local/lib/python2.7/dist-packages/django/bin/myste/opt/views.py", line 32, in opt_data
    s=json.dumps(p,cls=DateEncoder)
  File "/usr/lib/python2.7/json/__init__.py", line 250, in dumps
    sort_keys=sort_keys, **kw).encode(obj)
  File "/usr/lib/python2.7/json/encoder.py", line 207, in encode
    chunks = self.iterencode(o, _one_shot=True)
  File "/usr/lib/python2.7/json/encoder.py", line 270, in iterencode
    return _iterencode(o, 0)
  File "/usr/local/lib/python2.7/dist-packages/django/bin/myste/opt/views.py", line 20, in default
    return json.JSONEncoder.default(self,obj)
  File "/usr/lib/python2.7/json/encoder.py", line 184, in default
    raise TypeError(repr(o) + " is not JSON serializable")
TypeError: datetime.date(2014, 7, 24) is not JSON serializable
2014-07-26 07:44:16,903 [Thread-12:-1274025152] [django.request:224] [ERROR]- Internal Server Error: /test1/
Traceback (most recent call last):
  File "/usr/local/lib/python2.7/dist-packages/django/core/handlers/base.py", line 112, in get_response
    response = wrapped_callback(request, *callback_args, **callback_kwargs)
  File "/usr/local/lib/python2.7/dist-packages/django/bin/myste/opt/views.py", line 32, in opt_data
    s=json.dumps(p,cls=DateEncoder)
  File "/usr/lib/python2.7/json/__init__.py", line 250, in dumps
    sort_keys=sort_keys, **kw).encode(obj)
  File "/usr/lib/python2.7/json/encoder.py", line 207, in encode
    chunks = self.iterencode(o, _one_shot=True)
  File "/usr/lib/python2.7/json/encoder.py", line 270, in iterencode
    return _iterencode(o, 0)
  File "/usr/local/lib/python2.7/dist-packages/django/bin/myste/opt/views.py", line 20, in default
    return json.JSONEncoder.default(self,obj)
  File "/usr/lib/python2.7/json/encoder.py", line 184, in default
    raise TypeError(repr(o) + " is not JSON serializable")
TypeError: datetime.date(2014, 7, 24) is not JSON serializable
2014-07-26 07:44:20,738 [Thread-13:-1274025152] [django.request:224] [ERROR]- Internal Server Error: /test1/
Traceback (most recent call last):
  File "/usr/local/lib/python2.7/dist-packages/django/core/handlers/base.py", line 112, in get_response
    response = wrapped_callback(request, *callback_args, **callback_kwargs)
  File "/usr/local/lib/python2.7/dist-packages/django/bin/myste/opt/views.py", line 32, in opt_data
    s=json.dumps(p,cls=DateEncoder)
  File "/usr/lib/python2.7/json/__init__.py", line 250, in dumps
    sort_keys=sort_keys, **kw).encode(obj)
  File "/usr/lib/python2.7/json/encoder.py", line 207, in encode
    chunks = self.iterencode(o, _one_shot=True)
  File "/usr/lib/python2.7/json/encoder.py", line 270, in iterencode
    return _iterencode(o, 0)
  File "/usr/local/lib/python2.7/dist-packages/django/bin/myste/opt/views.py", line 20, in default
    return json.JSONEncoder.default(self,obj)
  File "/usr/lib/python2.7/json/encoder.py", line 184, in default
    raise TypeError(repr(o) + " is not JSON serializable")
TypeError: datetime.date(2014, 7, 24) is not JSON serializable
2014-07-26 07:44:21,204 [Thread-14:-1274025152] [django.request:224] [ERROR]- Internal Server Error: /test1/
Traceback (most recent call last):
  File "/usr/local/lib/python2.7/dist-packages/django/core/handlers/base.py", line 112, in get_response
    response = wrapped_callback(request, *callback_args, **callback_kwargs)
  File "/usr/local/lib/python2.7/dist-packages/django/bin/myste/opt/views.py", line 32, in opt_data
    s=json.dumps(p,cls=DateEncoder)
  File "/usr/lib/python2.7/json/__init__.py", line 250, in dumps
    sort_keys=sort_keys, **kw).encode(obj)
  File "/usr/lib/python2.7/json/encoder.py", line 207, in encode
    chunks = self.iterencode(o, _one_shot=True)
  File "/usr/lib/python2.7/json/encoder.py", line 270, in iterencode
    return _iterencode(o, 0)
  File "/usr/local/lib/python2.7/dist-packages/django/bin/myste/opt/views.py", line 20, in default
    return json.JSONEncoder.default(self,obj)
  File "/usr/lib/python2.7/json/encoder.py", line 184, in default
    raise TypeError(repr(o) + " is not JSON serializable")
TypeError: datetime.date(2014, 7, 24) is not JSON serializable
2014-07-26 07:55:58,403 [Thread-15:-1274025152] [django.request:224] [ERROR]- Internal Server Error: /test1/
Traceback (most recent call last):
  File "/usr/local/lib/python2.7/dist-packages/django/core/handlers/base.py", line 112, in get_response
    response = wrapped_callback(request, *callback_args, **callback_kwargs)
  File "/usr/local/lib/python2.7/dist-packages/django/bin/myste/opt/views.py", line 32, in opt_data
    s=json.dumps(p,cls=DateEncoder)
  File "/usr/lib/python2.7/json/__init__.py", line 250, in dumps
    sort_keys=sort_keys, **kw).encode(obj)
  File "/usr/lib/python2.7/json/encoder.py", line 207, in encode
    chunks = self.iterencode(o, _one_shot=True)
  File "/usr/lib/python2.7/json/encoder.py", line 270, in iterencode
    return _iterencode(o, 0)
  File "/usr/local/lib/python2.7/dist-packages/django/bin/myste/opt/views.py", line 20, in default
    return json.JSONEncoder.default(self,obj)
  File "/usr/lib/python2.7/json/encoder.py", line 184, in default
    raise TypeError(repr(o) + " is not JSON serializable")
TypeError: datetime.date(2014, 7, 24) is not JSON serializable
2014-07-26 07:56:05,151 [Thread-16:-1274025152] [django.request:224] [ERROR]- Internal Server Error: /test1/
Traceback (most recent call last):
  File "/usr/local/lib/python2.7/dist-packages/django/core/handlers/base.py", line 112, in get_response
    response = wrapped_callback(request, *callback_args, **callback_kwargs)
  File "/usr/local/lib/python2.7/dist-packages/django/bin/myste/opt/views.py", line 32, in opt_data
    s=json.dumps(p,cls=DateEncoder)
  File "/usr/lib/python2.7/json/__init__.py", line 250, in dumps
    sort_keys=sort_keys, **kw).encode(obj)
  File "/usr/lib/python2.7/json/encoder.py", line 207, in encode
    chunks = self.iterencode(o, _one_shot=True)
  File "/usr/lib/python2.7/json/encoder.py", line 270, in iterencode
    return _iterencode(o, 0)
  File "/usr/local/lib/python2.7/dist-packages/django/bin/myste/opt/views.py", line 20, in default
    return json.JSONEncoder.default(self,obj)
  File "/usr/lib/python2.7/json/encoder.py", line 184, in default
    raise TypeError(repr(o) + " is not JSON serializable")
TypeError: datetime.date(2014, 7, 24) is not JSON serializable
2014-07-26 10:02:01,455 [Thread-3:-1256195264] [django.request:224] [ERROR]- Internal Server Error: /test1/
Traceback (most recent call last):
  File "/usr/local/lib/python2.7/dist-packages/django/core/handlers/base.py", line 112, in get_response
    response = wrapped_callback(request, *callback_args, **callback_kwargs)
  File "/usr/local/lib/python2.7/dist-packages/django/bin/myste/opt/views.py", line 30, in opt_data
    for i in a:
  File "/usr/local/lib/python2.7/dist-packages/django/db/models/query.py", line 1398, in __iter__
    query = iter(self.query)
  File "/usr/local/lib/python2.7/dist-packages/django/db/models/sql/query.py", line 73, in __iter__
    self._execute_query()
  File "/usr/local/lib/python2.7/dist-packages/django/db/models/sql/query.py", line 87, in _execute_query
    self.cursor.execute(self.sql, self.params)
  File "/usr/local/lib/python2.7/dist-packages/django/db/backends/util.py", line 69, in execute
    return super(CursorDebugWrapper, self).execute(sql, params)
  File "/usr/local/lib/python2.7/dist-packages/django/db/backends/util.py", line 53, in execute
    return self.cursor.execute(sql, params)
  File "/usr/local/lib/python2.7/dist-packages/django/db/utils.py", line 99, in __exit__
    six.reraise(dj_exc_type, dj_exc_value, traceback)
  File "/usr/local/lib/python2.7/dist-packages/django/db/backends/util.py", line 53, in execute
    return self.cursor.execute(sql, params)
  File "/usr/local/lib/python2.7/dist-packages/django/db/backends/mysql/base.py", line 124, in execute
    return self.cursor.execute(query, args)
  File "/usr/lib/python2.7/dist-packages/MySQLdb/cursors.py", line 174, in execute
    self.errorhandler(self, exc, value)
  File "/usr/lib/python2.7/dist-packages/MySQLdb/connections.py", line 36, in defaulterrorhandler
    raise errorclass, errorvalue
ProgrammingError: (1064, "You have an error in your SQL syntax; check the manual that corresponds to your MySQL server version for the right syntax to use near '' at line 1")
