2014-10-04 01:06:07,344 [Thread-1:-1246758080] [django.request:224] [ERROR]- Internal Server Error: /login
Traceback (most recent call last):
  File "/usr/local/lib/python2.7/dist-packages/django/core/handlers/base.py", line 88, in get_response
    response = middleware_method(request)
  File "/usr/local/lib/python2.7/dist-packages/django/middleware/common.py", line 72, in process_request
    urlresolvers.is_valid_path("%s/" % request.path_info, urlconf)):
  File "/usr/local/lib/python2.7/dist-packages/django/core/urlresolvers.py", line 596, in is_valid_path
    resolve(path, urlconf)
  File "/usr/local/lib/python2.7/dist-packages/django/core/urlresolvers.py", line 476, in resolve
    return get_resolver(urlconf).resolve(path)
  File "/usr/local/lib/python2.7/dist-packages/django/core/urlresolvers.py", line 339, in resolve
    sub_match = pattern.resolve(new_path)
  File "/usr/local/lib/python2.7/dist-packages/django/core/urlresolvers.py", line 223, in resolve
    return ResolverMatch(self.callback, args, kwargs, self.name)
  File "/usr/local/lib/python2.7/dist-packages/django/core/urlresolvers.py", line 230, in callback
    self._callback = get_callable(self._callback_str)
  File "/usr/local/lib/python2.7/dist-packages/django/utils/functional.py", line 32, in wrapper
    result = func(*args)
  File "/usr/local/lib/python2.7/dist-packages/django/core/urlresolvers.py", line 97, in get_callable
    mod = import_module(mod_name)
  File "/usr/local/lib/python2.7/dist-packages/django/utils/importlib.py", line 40, in import_module
    __import__(name)
  File "/usr/local/lib/python2.7/dist-packages/django/bin/myste/opt/views.py", line 5, in <module>
    from forms import UserForm
  File "/usr/local/lib/python2.7/dist-packages/django/bin/myste/opt/forms.py", line 6, in <module>
    class UserForm(forms.Form):
  File "/usr/local/lib/python2.7/dist-packages/django/bin/myste/opt/forms.py", line 8, in UserForm
    password = form.CharField(label='密码',widget=forms.PasswordInput())
NameError: name 'form' is not defined
2014-10-04 01:06:07,769 [Thread-3:-1257243840] [django.request:143] [WARNING]- Not Found: /favicon.ico
2014-10-04 01:29:03,467 [Thread-4:-1257243840] [django.request:224] [ERROR]- Internal Server Error: /login
Traceback (most recent call last):
  File "/usr/local/lib/python2.7/dist-packages/django/core/handlers/base.py", line 88, in get_response
    response = middleware_method(request)
  File "/usr/local/lib/python2.7/dist-packages/django/middleware/common.py", line 72, in process_request
    urlresolvers.is_valid_path("%s/" % request.path_info, urlconf)):
  File "/usr/local/lib/python2.7/dist-packages/django/core/urlresolvers.py", line 596, in is_valid_path
    resolve(path, urlconf)
  File "/usr/local/lib/python2.7/dist-packages/django/core/urlresolvers.py", line 476, in resolve
    return get_resolver(urlconf).resolve(path)
  File "/usr/local/lib/python2.7/dist-packages/django/core/urlresolvers.py", line 339, in resolve
    sub_match = pattern.resolve(new_path)
  File "/usr/local/lib/python2.7/dist-packages/django/core/urlresolvers.py", line 223, in resolve
    return ResolverMatch(self.callback, args, kwargs, self.name)
  File "/usr/local/lib/python2.7/dist-packages/django/core/urlresolvers.py", line 230, in callback
    self._callback = get_callable(self._callback_str)
  File "/usr/local/lib/python2.7/dist-packages/django/utils/functional.py", line 32, in wrapper
    result = func(*args)
  File "/usr/local/lib/python2.7/dist-packages/django/core/urlresolvers.py", line 97, in get_callable
    mod = import_module(mod_name)
  File "/usr/local/lib/python2.7/dist-packages/django/utils/importlib.py", line 40, in import_module
    __import__(name)
  File "/usr/local/lib/python2.7/dist-packages/django/bin/myste/opt/views.py", line 5, in <module>
    from forms import UserForm
  File "/usr/local/lib/python2.7/dist-packages/django/bin/myste/opt/forms.py", line 6, in <module>
    class UserForm(forms.Form):
  File "/usr/local/lib/python2.7/dist-packages/django/bin/myste/opt/forms.py", line 8, in UserForm
    password = form.CharField(label='密码',widget=forms.PasswordInput())
NameError: name 'form' is not defined
2014-10-04 01:33:48,095 [Thread-6:-1246758080] [django.request:224] [ERROR]- Internal Server Error: /login
Traceback (most recent call last):
  File "/usr/local/lib/python2.7/dist-packages/django/core/handlers/base.py", line 88, in get_response
    response = middleware_method(request)
  File "/usr/local/lib/python2.7/dist-packages/django/middleware/common.py", line 72, in process_request
    urlresolvers.is_valid_path("%s/" % request.path_info, urlconf)):
  File "/usr/local/lib/python2.7/dist-packages/django/core/urlresolvers.py", line 596, in is_valid_path
    resolve(path, urlconf)
  File "/usr/local/lib/python2.7/dist-packages/django/core/urlresolvers.py", line 476, in resolve
    return get_resolver(urlconf).resolve(path)
  File "/usr/local/lib/python2.7/dist-packages/django/core/urlresolvers.py", line 339, in resolve
    sub_match = pattern.resolve(new_path)
  File "/usr/local/lib/python2.7/dist-packages/django/core/urlresolvers.py", line 223, in resolve
    return ResolverMatch(self.callback, args, kwargs, self.name)
  File "/usr/local/lib/python2.7/dist-packages/django/core/urlresolvers.py", line 230, in callback
    self._callback = get_callable(self._callback_str)
  File "/usr/local/lib/python2.7/dist-packages/django/utils/functional.py", line 32, in wrapper
    result = func(*args)
  File "/usr/local/lib/python2.7/dist-packages/django/core/urlresolvers.py", line 97, in get_callable
    mod = import_module(mod_name)
  File "/usr/local/lib/python2.7/dist-packages/django/utils/importlib.py", line 40, in import_module
    __import__(name)
  File "/usr/local/lib/python2.7/dist-packages/django/bin/myste/opt/views.py", line 5, in <module>
    from forms import UserForm
  File "/usr/local/lib/python2.7/dist-packages/django/bin/myste/opt/forms.py", line 2, in <module>
    from django import newforms as forms
ImportError: cannot import name newforms
2014-10-04 02:31:31,632 [Thread-8:-1257243840] [django.request:224] [ERROR]- Internal Server Error: /login
Traceback (most recent call last):
  File "/usr/local/lib/python2.7/dist-packages/django/core/handlers/base.py", line 88, in get_response
    response = middleware_method(request)
  File "/usr/local/lib/python2.7/dist-packages/django/middleware/common.py", line 72, in process_request
    urlresolvers.is_valid_path("%s/" % request.path_info, urlconf)):
  File "/usr/local/lib/python2.7/dist-packages/django/core/urlresolvers.py", line 596, in is_valid_path
    resolve(path, urlconf)
  File "/usr/local/lib/python2.7/dist-packages/django/core/urlresolvers.py", line 476, in resolve
    return get_resolver(urlconf).resolve(path)
  File "/usr/local/lib/python2.7/dist-packages/django/core/urlresolvers.py", line 339, in resolve
    sub_match = pattern.resolve(new_path)
  File "/usr/local/lib/python2.7/dist-packages/django/core/urlresolvers.py", line 223, in resolve
    return ResolverMatch(self.callback, args, kwargs, self.name)
  File "/usr/local/lib/python2.7/dist-packages/django/core/urlresolvers.py", line 230, in callback
    self._callback = get_callable(self._callback_str)
  File "/usr/local/lib/python2.7/dist-packages/django/utils/functional.py", line 32, in wrapper
    result = func(*args)
  File "/usr/local/lib/python2.7/dist-packages/django/core/urlresolvers.py", line 97, in get_callable
    mod = import_module(mod_name)
  File "/usr/local/lib/python2.7/dist-packages/django/utils/importlib.py", line 40, in import_module
    __import__(name)
  File "/usr/local/lib/python2.7/dist-packages/django/bin/myste/opt/views.py", line 5, in <module>
    from forms import UserForm
  File "/usr/local/lib/python2.7/dist-packages/django/bin/myste/opt/forms.py", line 2, in <module>
    from django import newforms as forms
ImportError: cannot import name newforms
2014-10-04 02:31:49,989 [Thread-10:-1246758080] [django.request:224] [ERROR]- Internal Server Error: /login
Traceback (most recent call last):
  File "/usr/local/lib/python2.7/dist-packages/django/core/handlers/base.py", line 88, in get_response
    response = middleware_method(request)
  File "/usr/local/lib/python2.7/dist-packages/django/middleware/common.py", line 72, in process_request
    urlresolvers.is_valid_path("%s/" % request.path_info, urlconf)):
  File "/usr/local/lib/python2.7/dist-packages/django/core/urlresolvers.py", line 596, in is_valid_path
    resolve(path, urlconf)
  File "/usr/local/lib/python2.7/dist-packages/django/core/urlresolvers.py", line 476, in resolve
    return get_resolver(urlconf).resolve(path)
  File "/usr/local/lib/python2.7/dist-packages/django/core/urlresolvers.py", line 339, in resolve
    sub_match = pattern.resolve(new_path)
  File "/usr/local/lib/python2.7/dist-packages/django/core/urlresolvers.py", line 223, in resolve
    return ResolverMatch(self.callback, args, kwargs, self.name)
  File "/usr/local/lib/python2.7/dist-packages/django/core/urlresolvers.py", line 230, in callback
    self._callback = get_callable(self._callback_str)
  File "/usr/local/lib/python2.7/dist-packages/django/utils/functional.py", line 32, in wrapper
    result = func(*args)
  File "/usr/local/lib/python2.7/dist-packages/django/core/urlresolvers.py", line 97, in get_callable
    mod = import_module(mod_name)
  File "/usr/local/lib/python2.7/dist-packages/django/utils/importlib.py", line 40, in import_module
    __import__(name)
  File "/usr/local/lib/python2.7/dist-packages/django/bin/myste/opt/views.py", line 5, in <module>
    from forms import UserForm
  File "/usr/local/lib/python2.7/dist-packages/django/bin/myste/opt/forms.py", line 2, in <module>
ImportError: cannot import name newforms
2014-10-04 02:31:52,293 [Thread-11:-1257243840] [django.request:224] [ERROR]- Internal Server Error: /login
Traceback (most recent call last):
  File "/usr/local/lib/python2.7/dist-packages/django/core/handlers/base.py", line 88, in get_response
    response = middleware_method(request)
  File "/usr/local/lib/python2.7/dist-packages/django/middleware/common.py", line 72, in process_request
    urlresolvers.is_valid_path("%s/" % request.path_info, urlconf)):
  File "/usr/local/lib/python2.7/dist-packages/django/core/urlresolvers.py", line 596, in is_valid_path
    resolve(path, urlconf)
  File "/usr/local/lib/python2.7/dist-packages/django/core/urlresolvers.py", line 476, in resolve
    return get_resolver(urlconf).resolve(path)
  File "/usr/local/lib/python2.7/dist-packages/django/core/urlresolvers.py", line 339, in resolve
    sub_match = pattern.resolve(new_path)
  File "/usr/local/lib/python2.7/dist-packages/django/core/urlresolvers.py", line 223, in resolve
    return ResolverMatch(self.callback, args, kwargs, self.name)
  File "/usr/local/lib/python2.7/dist-packages/django/core/urlresolvers.py", line 230, in callback
    self._callback = get_callable(self._callback_str)
  File "/usr/local/lib/python2.7/dist-packages/django/utils/functional.py", line 32, in wrapper
    result = func(*args)
  File "/usr/local/lib/python2.7/dist-packages/django/core/urlresolvers.py", line 97, in get_callable
    mod = import_module(mod_name)
  File "/usr/local/lib/python2.7/dist-packages/django/utils/importlib.py", line 40, in import_module
    __import__(name)
  File "/usr/local/lib/python2.7/dist-packages/django/bin/myste/opt/views.py", line 5, in <module>
    from forms import UserForm
  File "/usr/local/lib/python2.7/dist-packages/django/bin/myste/opt/forms.py", line 2, in <module>
ImportError: cannot import name newforms
2014-10-04 02:32:25,130 [Thread-1:-1246758080] [django.request:224] [ERROR]- Internal Server Error: /login
Traceback (most recent call last):
  File "/usr/local/lib/python2.7/dist-packages/django/core/handlers/base.py", line 88, in get_response
    response = middleware_method(request)
  File "/usr/local/lib/python2.7/dist-packages/django/middleware/common.py", line 72, in process_request
    urlresolvers.is_valid_path("%s/" % request.path_info, urlconf)):
  File "/usr/local/lib/python2.7/dist-packages/django/core/urlresolvers.py", line 596, in is_valid_path
    resolve(path, urlconf)
  File "/usr/local/lib/python2.7/dist-packages/django/core/urlresolvers.py", line 476, in resolve
    return get_resolver(urlconf).resolve(path)
  File "/usr/local/lib/python2.7/dist-packages/django/core/urlresolvers.py", line 339, in resolve
    sub_match = pattern.resolve(new_path)
  File "/usr/local/lib/python2.7/dist-packages/django/core/urlresolvers.py", line 223, in resolve
    return ResolverMatch(self.callback, args, kwargs, self.name)
  File "/usr/local/lib/python2.7/dist-packages/django/core/urlresolvers.py", line 230, in callback
    self._callback = get_callable(self._callback_str)
  File "/usr/local/lib/python2.7/dist-packages/django/utils/functional.py", line 32, in wrapper
    result = func(*args)
  File "/usr/local/lib/python2.7/dist-packages/django/core/urlresolvers.py", line 97, in get_callable
    mod = import_module(mod_name)
  File "/usr/local/lib/python2.7/dist-packages/django/utils/importlib.py", line 40, in import_module
    __import__(name)
  File "/usr/local/lib/python2.7/dist-packages/django/bin/myste/opt/views.py", line 5, in <module>
    from forms import UserForm
  File "/usr/local/lib/python2.7/dist-packages/django/bin/myste/opt/forms.py", line 2, in <module>
ImportError: cannot import name newforms
2014-10-04 02:34:27,056 [Thread-4:-1257243840] [django.request:224] [ERROR]- Internal Server Error: /login
Traceback (most recent call last):
  File "/usr/local/lib/python2.7/dist-packages/django/core/handlers/base.py", line 88, in get_response
    response = middleware_method(request)
  File "/usr/local/lib/python2.7/dist-packages/django/middleware/common.py", line 72, in process_request
    urlresolvers.is_valid_path("%s/" % request.path_info, urlconf)):
  File "/usr/local/lib/python2.7/dist-packages/django/core/urlresolvers.py", line 596, in is_valid_path
    resolve(path, urlconf)
  File "/usr/local/lib/python2.7/dist-packages/django/core/urlresolvers.py", line 476, in resolve
    return get_resolver(urlconf).resolve(path)
  File "/usr/local/lib/python2.7/dist-packages/django/core/urlresolvers.py", line 339, in resolve
    sub_match = pattern.resolve(new_path)
  File "/usr/local/lib/python2.7/dist-packages/django/core/urlresolvers.py", line 223, in resolve
    return ResolverMatch(self.callback, args, kwargs, self.name)
  File "/usr/local/lib/python2.7/dist-packages/django/core/urlresolvers.py", line 230, in callback
    self._callback = get_callable(self._callback_str)
  File "/usr/local/lib/python2.7/dist-packages/django/utils/functional.py", line 32, in wrapper
    result = func(*args)
  File "/usr/local/lib/python2.7/dist-packages/django/core/urlresolvers.py", line 97, in get_callable
    mod = import_module(mod_name)
  File "/usr/local/lib/python2.7/dist-packages/django/utils/importlib.py", line 40, in import_module
    __import__(name)
  File "/usr/local/lib/python2.7/dist-packages/django/bin/myste/opt/views.py", line 5, in <module>
    from forms import UserForm
  File "/usr/local/lib/python2.7/dist-packages/django/bin/myste/opt/forms.py", line 2, in <module>
    from django import newforms as forms
ImportError: cannot import name newforms
2014-10-04 02:34:29,781 [Thread-5:-1246758080] [django.request:224] [ERROR]- Internal Server Error: /login
Traceback (most recent call last):
  File "/usr/local/lib/python2.7/dist-packages/django/core/handlers/base.py", line 88, in get_response
    response = middleware_method(request)
  File "/usr/local/lib/python2.7/dist-packages/django/middleware/common.py", line 72, in process_request
    urlresolvers.is_valid_path("%s/" % request.path_info, urlconf)):
  File "/usr/local/lib/python2.7/dist-packages/django/core/urlresolvers.py", line 596, in is_valid_path
    resolve(path, urlconf)
  File "/usr/local/lib/python2.7/dist-packages/django/core/urlresolvers.py", line 476, in resolve
    return get_resolver(urlconf).resolve(path)
  File "/usr/local/lib/python2.7/dist-packages/django/core/urlresolvers.py", line 339, in resolve
    sub_match = pattern.resolve(new_path)
  File "/usr/local/lib/python2.7/dist-packages/django/core/urlresolvers.py", line 223, in resolve
    return ResolverMatch(self.callback, args, kwargs, self.name)
  File "/usr/local/lib/python2.7/dist-packages/django/core/urlresolvers.py", line 230, in callback
    self._callback = get_callable(self._callback_str)
  File "/usr/local/lib/python2.7/dist-packages/django/utils/functional.py", line 32, in wrapper
    result = func(*args)
  File "/usr/local/lib/python2.7/dist-packages/django/core/urlresolvers.py", line 97, in get_callable
    mod = import_module(mod_name)
  File "/usr/local/lib/python2.7/dist-packages/django/utils/importlib.py", line 40, in import_module
    __import__(name)
  File "/usr/local/lib/python2.7/dist-packages/django/bin/myste/opt/views.py", line 5, in <module>
    from forms import UserForm
  File "/usr/local/lib/python2.7/dist-packages/django/bin/myste/opt/forms.py", line 2, in <module>
    from django import newforms as forms
ImportError: cannot import name newforms
2014-10-04 02:36:33,004 [Thread-7:-1257243840] [django.request:224] [ERROR]- Internal Server Error: /login
Traceback (most recent call last):
  File "/usr/local/lib/python2.7/dist-packages/django/core/handlers/base.py", line 88, in get_response
    response = middleware_method(request)
  File "/usr/local/lib/python2.7/dist-packages/django/middleware/common.py", line 72, in process_request
    urlresolvers.is_valid_path("%s/" % request.path_info, urlconf)):
  File "/usr/local/lib/python2.7/dist-packages/django/core/urlresolvers.py", line 596, in is_valid_path
    resolve(path, urlconf)
  File "/usr/local/lib/python2.7/dist-packages/django/core/urlresolvers.py", line 476, in resolve
    return get_resolver(urlconf).resolve(path)
  File "/usr/local/lib/python2.7/dist-packages/django/core/urlresolvers.py", line 339, in resolve
    sub_match = pattern.resolve(new_path)
  File "/usr/local/lib/python2.7/dist-packages/django/core/urlresolvers.py", line 223, in resolve
    return ResolverMatch(self.callback, args, kwargs, self.name)
  File "/usr/local/lib/python2.7/dist-packages/django/core/urlresolvers.py", line 230, in callback
    self._callback = get_callable(self._callback_str)
  File "/usr/local/lib/python2.7/dist-packages/django/utils/functional.py", line 32, in wrapper
    result = func(*args)
  File "/usr/local/lib/python2.7/dist-packages/django/core/urlresolvers.py", line 97, in get_callable
    mod = import_module(mod_name)
  File "/usr/local/lib/python2.7/dist-packages/django/utils/importlib.py", line 40, in import_module
    __import__(name)
  File "/usr/local/lib/python2.7/dist-packages/django/bin/myste/opt/views.py", line 5, in <module>
    from forms import UserForm
  File "/usr/local/lib/python2.7/dist-packages/django/bin/myste/opt/forms.py", line 2, in <module>
    from django import newforms as forms
ImportError: cannot import name newforms
2014-10-04 02:36:35,945 [Thread-8:-1246758080] [django.request:224] [ERROR]- Internal Server Error: /login
Traceback (most recent call last):
  File "/usr/local/lib/python2.7/dist-packages/django/core/handlers/base.py", line 88, in get_response
    response = middleware_method(request)
  File "/usr/local/lib/python2.7/dist-packages/django/middleware/common.py", line 72, in process_request
    urlresolvers.is_valid_path("%s/" % request.path_info, urlconf)):
  File "/usr/local/lib/python2.7/dist-packages/django/core/urlresolvers.py", line 596, in is_valid_path
    resolve(path, urlconf)
  File "/usr/local/lib/python2.7/dist-packages/django/core/urlresolvers.py", line 476, in resolve
    return get_resolver(urlconf).resolve(path)
  File "/usr/local/lib/python2.7/dist-packages/django/core/urlresolvers.py", line 339, in resolve
    sub_match = pattern.resolve(new_path)
  File "/usr/local/lib/python2.7/dist-packages/django/core/urlresolvers.py", line 223, in resolve
    return ResolverMatch(self.callback, args, kwargs, self.name)
  File "/usr/local/lib/python2.7/dist-packages/django/core/urlresolvers.py", line 230, in callback
    self._callback = get_callable(self._callback_str)
  File "/usr/local/lib/python2.7/dist-packages/django/utils/functional.py", line 32, in wrapper
    result = func(*args)
  File "/usr/local/lib/python2.7/dist-packages/django/core/urlresolvers.py", line 97, in get_callable
    mod = import_module(mod_name)
  File "/usr/local/lib/python2.7/dist-packages/django/utils/importlib.py", line 40, in import_module
    __import__(name)
  File "/usr/local/lib/python2.7/dist-packages/django/bin/myste/opt/views.py", line 5, in <module>
    from forms import UserForm
  File "/usr/local/lib/python2.7/dist-packages/django/bin/myste/opt/forms.py", line 2, in <module>
    from django import newforms as forms
ImportError: cannot import name newforms
2014-10-04 02:41:16,093 [Thread-12:-1246758080] [django.request:224] [ERROR]- Internal Server Error: /login/
Traceback (most recent call last):
  File "/usr/local/lib/python2.7/dist-packages/django/core/handlers/base.py", line 112, in get_response
    response = wrapped_callback(request, *callback_args, **callback_kwargs)
  File "/usr/local/lib/python2.7/dist-packages/django/bin/myste/opt/views.py", line 195, in login
    username = request.POST['username']
  File "/usr/local/lib/python2.7/dist-packages/django/utils/datastructures.py", line 301, in __getitem__
    raise MultiValueDictKeyError(repr(key))
MultiValueDictKeyError: "'username'"
2014-10-04 02:41:19,906 [Thread-13:-1246758080] [django.request:224] [ERROR]- Internal Server Error: /login/
Traceback (most recent call last):
  File "/usr/local/lib/python2.7/dist-packages/django/core/handlers/base.py", line 112, in get_response
    response = wrapped_callback(request, *callback_args, **callback_kwargs)
  File "/usr/local/lib/python2.7/dist-packages/django/bin/myste/opt/views.py", line 195, in login
    username = request.POST['username']
  File "/usr/local/lib/python2.7/dist-packages/django/utils/datastructures.py", line 301, in __getitem__
    raise MultiValueDictKeyError(repr(key))
MultiValueDictKeyError: "'username'"
2014-10-04 03:03:55,978 [Thread-7:-1256195264] [django.request:224] [ERROR]- Internal Server Error: /login/
Traceback (most recent call last):
  File "/usr/local/lib/python2.7/dist-packages/django/core/handlers/base.py", line 112, in get_response
    response = wrapped_callback(request, *callback_args, **callback_kwargs)
  File "/usr/local/lib/python2.7/dist-packages/django/bin/myste/opt/views.py", line 195, in login
    username = request.POST['username']
  File "/usr/local/lib/python2.7/dist-packages/django/utils/datastructures.py", line 301, in __getitem__
    raise MultiValueDictKeyError(repr(key))
MultiValueDictKeyError: "'username'"
2014-10-04 06:46:32,016 [Thread-1:-1246024896] [django.request:224] [ERROR]- Internal Server Error: /login/
Traceback (most recent call last):
  File "/usr/local/lib/python2.7/dist-packages/django/core/handlers/base.py", line 99, in get_response
    resolver_match = resolver.resolve(request.path_info)
  File "/usr/local/lib/python2.7/dist-packages/django/core/urlresolvers.py", line 337, in resolve
    for pattern in self.url_patterns:
  File "/usr/local/lib/python2.7/dist-packages/django/core/urlresolvers.py", line 365, in url_patterns
    patterns = getattr(self.urlconf_module, "urlpatterns", self.urlconf_module)
  File "/usr/local/lib/python2.7/dist-packages/django/core/urlresolvers.py", line 360, in urlconf_module
    self._urlconf_module = import_module(self.urlconf_name)
  File "/usr/local/lib/python2.7/dist-packages/django/utils/importlib.py", line 40, in import_module
    __import__(name)
  File "/usr/local/lib/python2.7/dist-packages/django/bin/myste/myste/urls.py", line 4, in <module>
    admin.autodiscover()
  File "/usr/local/lib/python2.7/dist-packages/django/contrib/admin/__init__.py", line 29, in autodiscover
    import_module('%s.admin' % app)
  File "/usr/local/lib/python2.7/dist-packages/django/utils/importlib.py", line 40, in import_module
    __import__(name)
  File "/usr/local/lib/python2.7/dist-packages/django/bin/myste/opt/admin.py", line 7, in <module>
    admin.site.register(User,UserAdmin)
NameError: name 'User' is not defined
2014-10-04 06:47:56,639 [Thread-4:-1256195264] [django.request:224] [ERROR]- Internal Server Error: /login/
Traceback (most recent call last):
  File "/usr/local/lib/python2.7/dist-packages/django/core/handlers/base.py", line 112, in get_response
    response = wrapped_callback(request, *callback_args, **callback_kwargs)
  File "/usr/local/lib/python2.7/dist-packages/django/bin/myste/opt/views.py", line 195, in login
    username = request.POST['username']
  File "/usr/local/lib/python2.7/dist-packages/django/utils/datastructures.py", line 301, in __getitem__
    raise MultiValueDictKeyError(repr(key))
MultiValueDictKeyError: "'username'"
2014-10-04 06:49:46,106 [Thread-6:-1246024896] [django.request:224] [ERROR]- Internal Server Error: /login/
Traceback (most recent call last):
  File "/usr/local/lib/python2.7/dist-packages/django/core/handlers/base.py", line 112, in get_response
    response = wrapped_callback(request, *callback_args, **callback_kwargs)
  File "/usr/local/lib/python2.7/dist-packages/django/bin/myste/opt/views.py", line 195, in login
    username = request.POST['username']
  File "/usr/local/lib/python2.7/dist-packages/django/utils/datastructures.py", line 301, in __getitem__
    raise MultiValueDictKeyError(repr(key))
MultiValueDictKeyError: "'username'"
2014-11-14 01:35:23,293 [Thread-4:-1245971648] [django.request:143] [WARNING]- Not Found: /favicon.ico
2014-11-14 07:27:56,557 [Thread-3:-1243612352] [django.request:224] [ERROR]- Internal Server Error: /jump/
Traceback (most recent call last):
  File "/usr/local/lib/python2.7/dist-packages/django/core/handlers/base.py", line 112, in get_response
    response = wrapped_callback(request, *callback_args, **callback_kwargs)
  File "/usr/local/lib/python2.7/dist-packages/django/bin/myste/opt/views.py", line 264, in jump
    for o in qs:
  File "/usr/local/lib/python2.7/dist-packages/django/db/models/query.py", line 96, in __iter__
    self._fetch_all()
  File "/usr/local/lib/python2.7/dist-packages/django/db/models/query.py", line 857, in _fetch_all
    self._result_cache = list(self.iterator())
  File "/usr/local/lib/python2.7/dist-packages/django/db/models/query.py", line 220, in iterator
    for row in compiler.results_iter():
  File "/usr/local/lib/python2.7/dist-packages/django/db/models/sql/compiler.py", line 713, in results_iter
    for rows in self.execute_sql(MULTI):
  File "/usr/local/lib/python2.7/dist-packages/django/db/models/sql/compiler.py", line 776, in execute_sql
    sql, params = self.as_sql()
  File "/usr/local/lib/python2.7/dist-packages/django/db/models/sql/compiler.py", line 83, in as_sql
    out_cols, s_params = self.get_columns(with_col_aliases)
  File "/usr/local/lib/python2.7/dist-packages/django/db/models/sql/compiler.py", line 231, in get_columns
    col_aliases)
  File "/usr/local/lib/python2.7/dist-packages/django/db/models/sql/compiler.py", line 306, in get_default_columns
    r = '%s.%s' % (qn(alias), qn2(field.column))
  File "/usr/local/lib/python2.7/dist-packages/django/db/models/sql/compiler.py", line 61, in quote_name_unless_alias
    r = self.connection.ops.quote_name(name)
  File "/usr/local/lib/python2.7/dist-packages/django/db/backends/dummy/base.py", line 15, in complain
    raise ImproperlyConfigured("settings.DATABASES is improperly configured. "
ImproperlyConfigured: settings.DATABASES is improperly configured. Please supply the ENGINE value. Check settings documentation for more details.
2014-11-14 07:28:01,279 [Thread-4:-1243612352] [django.request:224] [ERROR]- Internal Server Error: /
Traceback (most recent call last):
  File "/usr/local/lib/python2.7/dist-packages/django/core/handlers/base.py", line 112, in get_response
    response = wrapped_callback(request, *callback_args, **callback_kwargs)
  File "/usr/local/lib/python2.7/dist-packages/django/bin/myste/opt/views.py", line 208, in login
    if request.user.is_authenticated():
  File "/usr/local/lib/python2.7/dist-packages/django/utils/functional.py", line 213, in inner
    self._setup()
  File "/usr/local/lib/python2.7/dist-packages/django/utils/functional.py", line 298, in _setup
    self._wrapped = self._setupfunc()
  File "/usr/local/lib/python2.7/dist-packages/django/contrib/auth/middleware.py", line 18, in <lambda>
    request.user = SimpleLazyObject(lambda: get_user(request))
  File "/usr/local/lib/python2.7/dist-packages/django/contrib/auth/middleware.py", line 10, in get_user
    request._cached_user = auth.get_user(request)
  File "/usr/local/lib/python2.7/dist-packages/django/contrib/auth/__init__.py", line 140, in get_user
    user_id = request.session[SESSION_KEY]
  File "/usr/local/lib/python2.7/dist-packages/django/contrib/sessions/backends/base.py", line 47, in __getitem__
    return self._session[key]
  File "/usr/local/lib/python2.7/dist-packages/django/contrib/sessions/backends/base.py", line 173, in _get_session
    self._session_cache = self.load()
  File "/usr/local/lib/python2.7/dist-packages/django/contrib/sessions/backends/db.py", line 20, in load
    expire_date__gt=timezone.now()
  File "/usr/local/lib/python2.7/dist-packages/django/db/models/manager.py", line 151, in get
    return self.get_queryset().get(*args, **kwargs)
  File "/usr/local/lib/python2.7/dist-packages/django/db/models/query.py", line 304, in get
    num = len(clone)
  File "/usr/local/lib/python2.7/dist-packages/django/db/models/query.py", line 77, in __len__
    self._fetch_all()
  File "/usr/local/lib/python2.7/dist-packages/django/db/models/query.py", line 857, in _fetch_all
    self._result_cache = list(self.iterator())
  File "/usr/local/lib/python2.7/dist-packages/django/db/models/query.py", line 220, in iterator
    for row in compiler.results_iter():
  File "/usr/local/lib/python2.7/dist-packages/django/db/models/sql/compiler.py", line 713, in results_iter
    for rows in self.execute_sql(MULTI):
  File "/usr/local/lib/python2.7/dist-packages/django/db/models/sql/compiler.py", line 776, in execute_sql
    sql, params = self.as_sql()
  File "/usr/local/lib/python2.7/dist-packages/django/db/models/sql/compiler.py", line 83, in as_sql
    out_cols, s_params = self.get_columns(with_col_aliases)
  File "/usr/local/lib/python2.7/dist-packages/django/db/models/sql/compiler.py", line 231, in get_columns
    col_aliases)
  File "/usr/local/lib/python2.7/dist-packages/django/db/models/sql/compiler.py", line 306, in get_default_columns
    r = '%s.%s' % (qn(alias), qn2(field.column))
  File "/usr/local/lib/python2.7/dist-packages/django/db/models/sql/compiler.py", line 61, in quote_name_unless_alias
    r = self.connection.ops.quote_name(name)
  File "/usr/local/lib/python2.7/dist-packages/django/db/backends/dummy/base.py", line 15, in complain
    raise ImproperlyConfigured("settings.DATABASES is improperly configured. "
ImproperlyConfigured: settings.DATABASES is improperly configured. Please supply the ENGINE value. Check settings documentation for more details.
2014-11-14 07:29:01,421 [Thread-8:-1243612352] [django.request:224] [ERROR]- Internal Server Error: /jump/
Traceback (most recent call last):
  File "/usr/local/lib/python2.7/dist-packages/django/core/handlers/base.py", line 112, in get_response
    response = wrapped_callback(request, *callback_args, **callback_kwargs)
  File "/usr/local/lib/python2.7/dist-packages/django/bin/myste/opt/views.py", line 264, in jump
    for o in qs:
  File "/usr/local/lib/python2.7/dist-packages/django/db/models/query.py", line 96, in __iter__
    self._fetch_all()
  File "/usr/local/lib/python2.7/dist-packages/django/db/models/query.py", line 857, in _fetch_all
    self._result_cache = list(self.iterator())
  File "/usr/local/lib/python2.7/dist-packages/django/db/models/query.py", line 220, in iterator
    for row in compiler.results_iter():
  File "/usr/local/lib/python2.7/dist-packages/django/db/models/sql/compiler.py", line 713, in results_iter
    for rows in self.execute_sql(MULTI):
  File "/usr/local/lib/python2.7/dist-packages/django/db/models/sql/compiler.py", line 776, in execute_sql
    sql, params = self.as_sql()
  File "/usr/local/lib/python2.7/dist-packages/django/db/models/sql/compiler.py", line 83, in as_sql
    out_cols, s_params = self.get_columns(with_col_aliases)
  File "/usr/local/lib/python2.7/dist-packages/django/db/models/sql/compiler.py", line 231, in get_columns
    col_aliases)
  File "/usr/local/lib/python2.7/dist-packages/django/db/models/sql/compiler.py", line 306, in get_default_columns
    r = '%s.%s' % (qn(alias), qn2(field.column))
  File "/usr/local/lib/python2.7/dist-packages/django/db/models/sql/compiler.py", line 61, in quote_name_unless_alias
    r = self.connection.ops.quote_name(name)
  File "/usr/local/lib/python2.7/dist-packages/django/db/backends/dummy/base.py", line 15, in complain
    raise ImproperlyConfigured("settings.DATABASES is improperly configured. "
ImproperlyConfigured: settings.DATABASES is improperly configured. Please supply the ENGINE value. Check settings documentation for more details.
2014-11-15 01:29:38,760 [Thread-3:-1257243840] [django.request:143] [WARNING]- Not Found: /favicon.ico
2014-11-15 03:06:58,057 [Thread-5:-1282147520] [django.request:224] [ERROR]- Internal Server Error: /com/
Traceback (most recent call last):
  File "/usr/local/lib/python2.7/dist-packages/django/core/handlers/base.py", line 112, in get_response
    response = wrapped_callback(request, *callback_args, **callback_kwargs)
  File "/usr/local/lib/python2.7/dist-packages/django/bin/myste/opt/views.py", line 356, in commit
    ft=request.POST['feature'].split(';')
  File "/usr/local/lib/python2.7/dist-packages/django/utils/datastructures.py", line 301, in __getitem__
    raise MultiValueDictKeyError(repr(key))
MultiValueDictKeyError: "'feature'"
2014-11-15 03:09:30,249 [Thread-1:-1246758080] [django.request:224] [ERROR]- Internal Server Error: /com/
Traceback (most recent call last):
  File "/usr/local/lib/python2.7/dist-packages/django/core/handlers/base.py", line 112, in get_response
    response = wrapped_callback(request, *callback_args, **callback_kwargs)
  File "/usr/local/lib/python2.7/dist-packages/django/bin/myste/opt/views.py", line 356, in commit
    ft=request.POST['feature'].split(';')
  File "/usr/local/lib/python2.7/dist-packages/django/utils/datastructures.py", line 301, in __getitem__
    raise MultiValueDictKeyError(repr(key))
MultiValueDictKeyError: "'feature'"
2014-11-15 03:09:43,652 [Thread-1:-1246758080] [django.request:224] [ERROR]- Internal Server Error: /com/
Traceback (most recent call last):
  File "/usr/local/lib/python2.7/dist-packages/django/core/handlers/base.py", line 112, in get_response
    response = wrapped_callback(request, *callback_args, **callback_kwargs)
  File "/usr/local/lib/python2.7/dist-packages/django/bin/myste/opt/views.py", line 356, in commit
    ft=request.POST['feature'].split(';')
  File "/usr/local/lib/python2.7/dist-packages/django/utils/datastructures.py", line 301, in __getitem__
    raise MultiValueDictKeyError(repr(key))
MultiValueDictKeyError: "'feature'"
2014-11-15 03:11:13,381 [Thread-1:-1246758080] [django.request:224] [ERROR]- Internal Server Error: /com/
Traceback (most recent call last):
  File "/usr/local/lib/python2.7/dist-packages/django/core/handlers/base.py", line 112, in get_response
    response = wrapped_callback(request, *callback_args, **callback_kwargs)
  File "/usr/local/lib/python2.7/dist-packages/django/bin/myste/opt/views.py", line 357, in commit
    print ft
NameError: global name 'ft' is not defined
2014-11-15 03:11:30,769 [Thread-1:-1247806656] [django.request:224] [ERROR]- Internal Server Error: /com/
Traceback (most recent call last):
  File "/usr/local/lib/python2.7/dist-packages/django/core/handlers/base.py", line 130, in get_response
    raise ValueError("The view %s.%s didn't return an HttpResponse object." % (callback.__module__, view_name))
ValueError: The view opt.views.commit didn't return an HttpResponse object.
2014-11-15 03:16:02,007 [Thread-4:-1247806656] [django.request:143] [WARNING]- Not Found: /commit
2014-11-15 03:16:08,536 [Thread-5:-1247806656] [django.request:224] [ERROR]- Internal Server Error: /com/
Traceback (most recent call last):
  File "/usr/local/lib/python2.7/dist-packages/django/core/handlers/base.py", line 130, in get_response
    raise ValueError("The view %s.%s didn't return an HttpResponse object." % (callback.__module__, view_name))
ValueError: The view opt.views.commit didn't return an HttpResponse object.
2014-11-15 05:15:29,983 [Thread-25:-1246758080] [django.request:224] [ERROR]- Internal Server Error: /com/
Traceback (most recent call last):
  File "/usr/local/lib/python2.7/dist-packages/django/core/handlers/base.py", line 112, in get_response
    response = wrapped_callback(request, *callback_args, **callback_kwargs)
  File "/usr/local/lib/python2.7/dist-packages/django/bin/myste/opt/views.py", line 376, in commit
    kw=list(set(request.GET['keywords'].split('\n')))
  File "/usr/local/lib/python2.7/dist-packages/django/utils/datastructures.py", line 301, in __getitem__
    raise MultiValueDictKeyError(repr(key))
MultiValueDictKeyError: "'keywords'"
2014-11-15 05:15:32,025 [Thread-26:-1246758080] [django.request:224] [ERROR]- Internal Server Error: /com/
Traceback (most recent call last):
  File "/usr/local/lib/python2.7/dist-packages/django/core/handlers/base.py", line 112, in get_response
    response = wrapped_callback(request, *callback_args, **callback_kwargs)
  File "/usr/local/lib/python2.7/dist-packages/django/bin/myste/opt/views.py", line 376, in commit
    kw=list(set(request.GET['keywords'].split('\n')))
  File "/usr/local/lib/python2.7/dist-packages/django/utils/datastructures.py", line 301, in __getitem__
    raise MultiValueDictKeyError(repr(key))
MultiValueDictKeyError: "'keywords'"
2014-11-15 05:15:43,068 [Thread-27:-1246758080] [django.request:224] [ERROR]- Internal Server Error: /com/
Traceback (most recent call last):
  File "/usr/local/lib/python2.7/dist-packages/django/core/handlers/base.py", line 112, in get_response
    response = wrapped_callback(request, *callback_args, **callback_kwargs)
  File "/usr/local/lib/python2.7/dist-packages/django/bin/myste/opt/views.py", line 376, in commit
    kw=list(set(request.GET['keywords'].split('\n')))
  File "/usr/local/lib/python2.7/dist-packages/django/utils/datastructures.py", line 301, in __getitem__
    raise MultiValueDictKeyError(repr(key))
MultiValueDictKeyError: "'keywords'"
2014-11-15 05:15:43,619 [Thread-28:-1246758080] [django.request:224] [ERROR]- Internal Server Error: /com/
Traceback (most recent call last):
  File "/usr/local/lib/python2.7/dist-packages/django/core/handlers/base.py", line 112, in get_response
    response = wrapped_callback(request, *callback_args, **callback_kwargs)
  File "/usr/local/lib/python2.7/dist-packages/django/bin/myste/opt/views.py", line 376, in commit
    kw=list(set(request.GET['keywords'].split('\n')))
  File "/usr/local/lib/python2.7/dist-packages/django/utils/datastructures.py", line 301, in __getitem__
    raise MultiValueDictKeyError(repr(key))
MultiValueDictKeyError: "'keywords'"
2014-11-15 05:15:43,852 [Thread-29:-1246758080] [django.request:224] [ERROR]- Internal Server Error: /com/
Traceback (most recent call last):
  File "/usr/local/lib/python2.7/dist-packages/django/core/handlers/base.py", line 112, in get_response
    response = wrapped_callback(request, *callback_args, **callback_kwargs)
  File "/usr/local/lib/python2.7/dist-packages/django/bin/myste/opt/views.py", line 376, in commit
    kw=list(set(request.GET['keywords'].split('\n')))
  File "/usr/local/lib/python2.7/dist-packages/django/utils/datastructures.py", line 301, in __getitem__
    raise MultiValueDictKeyError(repr(key))
MultiValueDictKeyError: "'keywords'"
2014-11-15 05:15:44,028 [Thread-30:-1246758080] [django.request:224] [ERROR]- Internal Server Error: /com/
Traceback (most recent call last):
  File "/usr/local/lib/python2.7/dist-packages/django/core/handlers/base.py", line 112, in get_response
    response = wrapped_callback(request, *callback_args, **callback_kwargs)
  File "/usr/local/lib/python2.7/dist-packages/django/bin/myste/opt/views.py", line 376, in commit
    kw=list(set(request.GET['keywords'].split('\n')))
  File "/usr/local/lib/python2.7/dist-packages/django/utils/datastructures.py", line 301, in __getitem__
    raise MultiValueDictKeyError(repr(key))
MultiValueDictKeyError: "'keywords'"
2014-11-15 05:15:54,539 [Thread-31:-1246758080] [django.request:224] [ERROR]- Internal Server Error: /com/
Traceback (most recent call last):
  File "/usr/local/lib/python2.7/dist-packages/django/core/handlers/base.py", line 112, in get_response
    response = wrapped_callback(request, *callback_args, **callback_kwargs)
  File "/usr/local/lib/python2.7/dist-packages/django/bin/myste/opt/views.py", line 376, in commit
    kw=list(set(request.GET['keywords'].split('\n')))
  File "/usr/local/lib/python2.7/dist-packages/django/utils/datastructures.py", line 301, in __getitem__
    raise MultiValueDictKeyError(repr(key))
MultiValueDictKeyError: "'keywords'"
2014-11-15 05:17:14,271 [Thread-34:-1267729600] [django.request:224] [ERROR]- Internal Server Error: /com/
Traceback (most recent call last):
  File "/usr/local/lib/python2.7/dist-packages/django/core/handlers/base.py", line 112, in get_response
    response = wrapped_callback(request, *callback_args, **callback_kwargs)
  File "/usr/local/lib/python2.7/dist-packages/django/bin/myste/opt/views.py", line 376, in commit
    kw=list(set(request.GET['keywords'].split('\n')))
  File "/usr/local/lib/python2.7/dist-packages/django/utils/datastructures.py", line 301, in __getitem__
    raise MultiValueDictKeyError(repr(key))
MultiValueDictKeyError: "'keywords'"
2014-11-15 05:19:54,879 [Thread-35:-1267729600] [django.request:224] [ERROR]- Internal Server Error: /com/
Traceback (most recent call last):
  File "/usr/local/lib/python2.7/dist-packages/django/core/handlers/base.py", line 112, in get_response
    response = wrapped_callback(request, *callback_args, **callback_kwargs)
  File "/usr/local/lib/python2.7/dist-packages/django/bin/myste/opt/views.py", line 376, in commit
    kw=list(set(request.GET['keywords'].split('\n')))
  File "/usr/local/lib/python2.7/dist-packages/django/utils/datastructures.py", line 301, in __getitem__
    raise MultiValueDictKeyError(repr(key))
MultiValueDictKeyError: "'keywords'"
2014-11-15 05:19:55,521 [Thread-36:-1267729600] [django.request:224] [ERROR]- Internal Server Error: /com/
Traceback (most recent call last):
  File "/usr/local/lib/python2.7/dist-packages/django/core/handlers/base.py", line 112, in get_response
    response = wrapped_callback(request, *callback_args, **callback_kwargs)
  File "/usr/local/lib/python2.7/dist-packages/django/bin/myste/opt/views.py", line 376, in commit
    kw=list(set(request.GET['keywords'].split('\n')))
  File "/usr/local/lib/python2.7/dist-packages/django/utils/datastructures.py", line 301, in __getitem__
    raise MultiValueDictKeyError(repr(key))
MultiValueDictKeyError: "'keywords'"
2014-11-15 05:19:55,738 [Thread-37:-1267729600] [django.request:224] [ERROR]- Internal Server Error: /com/
Traceback (most recent call last):
  File "/usr/local/lib/python2.7/dist-packages/django/core/handlers/base.py", line 112, in get_response
    response = wrapped_callback(request, *callback_args, **callback_kwargs)
  File "/usr/local/lib/python2.7/dist-packages/django/bin/myste/opt/views.py", line 376, in commit
    kw=list(set(request.GET['keywords'].split('\n')))
  File "/usr/local/lib/python2.7/dist-packages/django/utils/datastructures.py", line 301, in __getitem__
    raise MultiValueDictKeyError(repr(key))
MultiValueDictKeyError: "'keywords'"
2014-11-15 05:20:53,619 [Thread-38:-1267729600] [django.request:224] [ERROR]- Internal Server Error: /com/
Traceback (most recent call last):
  File "/usr/local/lib/python2.7/dist-packages/django/core/handlers/base.py", line 112, in get_response
    response = wrapped_callback(request, *callback_args, **callback_kwargs)
  File "/usr/local/lib/python2.7/dist-packages/django/bin/myste/opt/views.py", line 376, in commit
    kw=list(set(request.GET['keywords'].split('\n')))
  File "/usr/local/lib/python2.7/dist-packages/django/utils/datastructures.py", line 301, in __getitem__
    raise MultiValueDictKeyError(repr(key))
MultiValueDictKeyError: "'keywords'"
2014-11-15 05:21:10,679 [Thread-41:-1246758080] [django.request:224] [ERROR]- Internal Server Error: /com/
Traceback (most recent call last):
  File "/usr/local/lib/python2.7/dist-packages/django/core/handlers/base.py", line 112, in get_response
    response = wrapped_callback(request, *callback_args, **callback_kwargs)
  File "/usr/local/lib/python2.7/dist-packages/django/bin/myste/opt/views.py", line 376, in commit
    kw=list(set(request.GET['keywords'].split('\n')))
  File "/usr/local/lib/python2.7/dist-packages/django/utils/datastructures.py", line 301, in __getitem__
    raise MultiValueDictKeyError(repr(key))
MultiValueDictKeyError: "'keywords'"
2014-11-15 05:21:31,574 [Thread-42:-1246758080] [django.request:224] [ERROR]- Internal Server Error: /com/
Traceback (most recent call last):
  File "/usr/local/lib/python2.7/dist-packages/django/core/handlers/base.py", line 112, in get_response
    response = wrapped_callback(request, *callback_args, **callback_kwargs)
  File "/usr/local/lib/python2.7/dist-packages/django/bin/myste/opt/views.py", line 376, in commit
    kw=list(set(request.GET['keywords'].split('\n')))
  File "/usr/local/lib/python2.7/dist-packages/django/utils/datastructures.py", line 301, in __getitem__
    raise MultiValueDictKeyError(repr(key))
MultiValueDictKeyError: "'keywords'"
2014-11-15 05:21:31,782 [Thread-43:-1246758080] [django.request:224] [ERROR]- Internal Server Error: /com/
Traceback (most recent call last):
  File "/usr/local/lib/python2.7/dist-packages/django/core/handlers/base.py", line 112, in get_response
    response = wrapped_callback(request, *callback_args, **callback_kwargs)
  File "/usr/local/lib/python2.7/dist-packages/django/bin/myste/opt/views.py", line 376, in commit
    kw=list(set(request.GET['keywords'].split('\n')))
  File "/usr/local/lib/python2.7/dist-packages/django/utils/datastructures.py", line 301, in __getitem__
    raise MultiValueDictKeyError(repr(key))
MultiValueDictKeyError: "'keywords'"
2014-11-15 05:21:31,975 [Thread-44:-1246758080] [django.request:224] [ERROR]- Internal Server Error: /com/
Traceback (most recent call last):
  File "/usr/local/lib/python2.7/dist-packages/django/core/handlers/base.py", line 112, in get_response
    response = wrapped_callback(request, *callback_args, **callback_kwargs)
  File "/usr/local/lib/python2.7/dist-packages/django/bin/myste/opt/views.py", line 376, in commit
    kw=list(set(request.GET['keywords'].split('\n')))
  File "/usr/local/lib/python2.7/dist-packages/django/utils/datastructures.py", line 301, in __getitem__
    raise MultiValueDictKeyError(repr(key))
MultiValueDictKeyError: "'keywords'"
2014-11-15 05:22:59,626 [Thread-4:-1267729600] [django.request:224] [ERROR]- Internal Server Error: /com/
Traceback (most recent call last):
  File "/usr/local/lib/python2.7/dist-packages/django/core/handlers/base.py", line 112, in get_response
    response = wrapped_callback(request, *callback_args, **callback_kwargs)
  File "/usr/local/lib/python2.7/dist-packages/django/bin/myste/opt/views.py", line 376, in commit
    kw=list(set(request.GET['keywords'].split('\n')))
  File "/usr/local/lib/python2.7/dist-packages/django/utils/datastructures.py", line 301, in __getitem__
    raise MultiValueDictKeyError(repr(key))
MultiValueDictKeyError: "'keywords'"
2014-11-15 05:23:31,113 [Thread-7:-1267729600] [django.request:224] [ERROR]- Internal Server Error: /com/
Traceback (most recent call last):
  File "/usr/local/lib/python2.7/dist-packages/django/core/handlers/base.py", line 112, in get_response
    response = wrapped_callback(request, *callback_args, **callback_kwargs)
  File "/usr/local/lib/python2.7/dist-packages/django/bin/myste/opt/views.py", line 376, in commit
    kw=list(set(request.GET['keywords'].split('\n')))
  File "/usr/local/lib/python2.7/dist-packages/django/utils/datastructures.py", line 301, in __getitem__
    raise MultiValueDictKeyError(repr(key))
MultiValueDictKeyError: "'keywords'"
2014-11-15 05:25:58,660 [Thread-4:-1267729600] [django.request:224] [ERROR]- Internal Server Error: /com/
Traceback (most recent call last):
  File "/usr/local/lib/python2.7/dist-packages/django/core/handlers/base.py", line 112, in get_response
    response = wrapped_callback(request, *callback_args, **callback_kwargs)
  File "/usr/local/lib/python2.7/dist-packages/django/bin/myste/opt/views.py", line 376, in commit
    kw=list(set(request.GET['keywords'].split('\n')))
  File "/usr/local/lib/python2.7/dist-packages/django/utils/datastructures.py", line 301, in __getitem__
    raise MultiValueDictKeyError(repr(key))
MultiValueDictKeyError: "'keywords'"
2014-11-15 07:35:20,279 [Thread-1:-1246758080] [django.request:224] [ERROR]- Internal Server Error: /cov/
Traceback (most recent call last):
  File "/usr/local/lib/python2.7/dist-packages/django/core/handlers/base.py", line 112, in get_response
    response = wrapped_callback(request, *callback_args, **callback_kwargs)
  File "/usr/local/lib/python2.7/dist-packages/django/bin/myste/opt/views.py", line 232, in cov
    if request.meathod == "GET":
AttributeError: 'WSGIRequest' object has no attribute 'meathod'
2014-11-15 07:37:20,368 [Thread-6:-1246758080] [django.request:224] [ERROR]- Internal Server Error: /jump
Traceback (most recent call last):
  File "/usr/local/lib/python2.7/dist-packages/django/core/handlers/base.py", line 88, in get_response
    response = middleware_method(request)
  File "/usr/local/lib/python2.7/dist-packages/django/middleware/common.py", line 72, in process_request
    urlresolvers.is_valid_path("%s/" % request.path_info, urlconf)):
  File "/usr/local/lib/python2.7/dist-packages/django/core/urlresolvers.py", line 596, in is_valid_path
    resolve(path, urlconf)
  File "/usr/local/lib/python2.7/dist-packages/django/core/urlresolvers.py", line 476, in resolve
    return get_resolver(urlconf).resolve(path)
  File "/usr/local/lib/python2.7/dist-packages/django/core/urlresolvers.py", line 339, in resolve
    sub_match = pattern.resolve(new_path)
  File "/usr/local/lib/python2.7/dist-packages/django/core/urlresolvers.py", line 223, in resolve
    return ResolverMatch(self.callback, args, kwargs, self.name)
  File "/usr/local/lib/python2.7/dist-packages/django/core/urlresolvers.py", line 230, in callback
    self._callback = get_callable(self._callback_str)
  File "/usr/local/lib/python2.7/dist-packages/django/utils/functional.py", line 32, in wrapper
    result = func(*args)
  File "/usr/local/lib/python2.7/dist-packages/django/core/urlresolvers.py", line 118, in get_callable
    (lookup_view, mod_name))
ViewDoesNotExist: Could not import opt.views.jump. View does not exist in module opt.views.
2014-11-15 07:44:12,589 [Thread-12:-1246758080] [django.request:143] [WARNING]- Not Found: /commit
2014-11-15 07:44:15,448 [Thread-13:-1246758080] [django.request:143] [WARNING]- Not Found: /commit
2014-11-15 07:57:12,809 [Thread-6:-1276122304] [django.request:143] [WARNING]- Not Found: /cov/
2014-11-15 07:57:19,608 [Thread-7:-1276122304] [django.request:143] [WARNING]- Not Found: /cov/
2014-11-15 07:57:33,048 [Thread-8:-1276122304] [django.request:143] [WARNING]- Not Found: /cov/
2014-11-15 07:57:33,873 [Thread-9:-1276122304] [django.request:143] [WARNING]- Not Found: /cov/
2014-11-15 07:57:34,073 [Thread-10:-1276122304] [django.request:143] [WARNING]- Not Found: /cov/
2014-11-15 07:57:34,248 [Thread-11:-1276122304] [django.request:143] [WARNING]- Not Found: /cov/
2014-11-15 07:57:34,418 [Thread-12:-1276122304] [django.request:143] [WARNING]- Not Found: /cov/
2014-11-15 07:57:34,554 [Thread-13:-1276122304] [django.request:143] [WARNING]- Not Found: /cov/
2014-11-15 07:57:34,841 [Thread-14:-1276122304] [django.request:143] [WARNING]- Not Found: /cov/
2014-11-15 07:57:35,034 [Thread-15:-1276122304] [django.request:143] [WARNING]- Not Found: /cov/
2014-11-15 07:57:35,489 [Thread-16:-1276122304] [django.request:143] [WARNING]- Not Found: /cov/
2014-11-15 07:57:35,714 [Thread-17:-1276122304] [django.request:143] [WARNING]- Not Found: /cov/
2014-11-15 07:57:35,905 [Thread-18:-1276122304] [django.request:143] [WARNING]- Not Found: /cov/
2014-11-15 07:57:36,121 [Thread-19:-1276122304] [django.request:143] [WARNING]- Not Found: /cov/
2014-11-15 07:57:36,331 [Thread-20:-1276122304] [django.request:143] [WARNING]- Not Found: /cov/
2014-11-15 07:57:36,533 [Thread-21:-1276122304] [django.request:143] [WARNING]- Not Found: /cov/
2014-11-15 07:57:36,724 [Thread-22:-1276122304] [django.request:143] [WARNING]- Not Found: /cov/
2014-11-15 07:57:36,928 [Thread-23:-1276122304] [django.request:143] [WARNING]- Not Found: /cov/
2014-11-15 07:57:37,147 [Thread-24:-1276122304] [django.request:143] [WARNING]- Not Found: /cov/
2014-11-15 07:57:37,376 [Thread-25:-1276122304] [django.request:143] [WARNING]- Not Found: /cov/
2014-11-15 07:57:37,641 [Thread-26:-1276122304] [django.request:143] [WARNING]- Not Found: /cov/
2014-11-15 07:57:37,866 [Thread-27:-1276122304] [django.request:143] [WARNING]- Not Found: /cov/
2014-11-15 07:57:38,122 [Thread-28:-1276122304] [django.request:143] [WARNING]- Not Found: /cov/
2014-11-15 07:57:39,618 [Thread-29:-1276122304] [django.request:143] [WARNING]- Not Found: /cov/
2014-11-15 07:57:39,840 [Thread-30:-1276122304] [django.request:143] [WARNING]- Not Found: /cov/
2014-11-15 07:57:40,018 [Thread-31:-1276122304] [django.request:143] [WARNING]- Not Found: /cov/
2014-11-15 07:57:46,420 [Thread-32:-1276122304] [django.request:143] [WARNING]- Not Found: /cov/
2014-11-15 07:58:26,672 [Thread-7:-1273234624] [django.request:143] [WARNING]- Not Found: /commit
2014-11-15 08:06:05,775 [Thread-1:-1246758080] [django.request:143] [WARNING]- Not Found: /cov/
2014-11-15 08:07:08,636 [Thread-15:-1275069632] [django.request:143] [WARNING]- Not Found: /com/
2014-11-15 08:07:11,914 [Thread-16:-1275069632] [django.request:143] [WARNING]- Not Found: /com/
2014-11-15 08:07:12,737 [Thread-17:-1275069632] [django.request:143] [WARNING]- Not Found: /com/
2014-11-15 08:07:12,954 [Thread-18:-1275069632] [django.request:143] [WARNING]- Not Found: /com/
