2014-10-04 01:06:07,344 [Thread-1:-1246758080] [django.request:224] [ERROR]- Internal Server Error: /login
Traceback (most recent call last):
  File "/usr/local/lib/python2.7/dist-packages/django/core/handlers/base.py", line 88, in get_response
    response = middleware_method(request)
  File "/usr/local/lib/python2.7/dist-packages/django/middleware/common.py", line 72, in process_request
    urlresolvers.is_valid_path("%s/" % request.path_info, urlconf)):
  File "/usr/local/lib/python2.7/dist-packages/django/core/urlresolvers.py", line 596, in is_valid_path
    resolve(path, urlconf)
  File "/usr/local/lib/python2.7/dist-packages/django/core/urlresolvers.py", line 476, in resolve
    return get_resolver(urlconf).resolve(path)
  File "/usr/local/lib/python2.7/dist-packages/django/core/urlresolvers.py", line 339, in resolve
    sub_match = pattern.resolve(new_path)
  File "/usr/local/lib/python2.7/dist-packages/django/core/urlresolvers.py", line 223, in resolve
    return ResolverMatch(self.callback, args, kwargs, self.name)
  File "/usr/local/lib/python2.7/dist-packages/django/core/urlresolvers.py", line 230, in callback
    self._callback = get_callable(self._callback_str)
  File "/usr/local/lib/python2.7/dist-packages/django/utils/functional.py", line 32, in wrapper
    result = func(*args)
  File "/usr/local/lib/python2.7/dist-packages/django/core/urlresolvers.py", line 97, in get_callable
    mod = import_module(mod_name)
  File "/usr/local/lib/python2.7/dist-packages/django/utils/importlib.py", line 40, in import_module
    __import__(name)
  File "/usr/local/lib/python2.7/dist-packages/django/bin/myste/opt/views.py", line 5, in <module>
    from forms import UserForm
  File "/usr/local/lib/python2.7/dist-packages/django/bin/myste/opt/forms.py", line 6, in <module>
    class UserForm(forms.Form):
  File "/usr/local/lib/python2.7/dist-packages/django/bin/myste/opt/forms.py", line 8, in UserForm
    password = form.CharField(label='密码',widget=forms.PasswordInput())
NameError: name 'form' is not defined
2014-10-04 01:06:07,769 [Thread-3:-1257243840] [django.request:143] [WARNING]- Not Found: /favicon.ico
2014-10-04 01:29:03,467 [Thread-4:-1257243840] [django.request:224] [ERROR]- Internal Server Error: /login
Traceback (most recent call last):
  File "/usr/local/lib/python2.7/dist-packages/django/core/handlers/base.py", line 88, in get_response
    response = middleware_method(request)
  File "/usr/local/lib/python2.7/dist-packages/django/middleware/common.py", line 72, in process_request
    urlresolvers.is_valid_path("%s/" % request.path_info, urlconf)):
  File "/usr/local/lib/python2.7/dist-packages/django/core/urlresolvers.py", line 596, in is_valid_path
    resolve(path, urlconf)
  File "/usr/local/lib/python2.7/dist-packages/django/core/urlresolvers.py", line 476, in resolve
    return get_resolver(urlconf).resolve(path)
  File "/usr/local/lib/python2.7/dist-packages/django/core/urlresolvers.py", line 339, in resolve
    sub_match = pattern.resolve(new_path)
  File "/usr/local/lib/python2.7/dist-packages/django/core/urlresolvers.py", line 223, in resolve
    return ResolverMatch(self.callback, args, kwargs, self.name)
  File "/usr/local/lib/python2.7/dist-packages/django/core/urlresolvers.py", line 230, in callback
    self._callback = get_callable(self._callback_str)
  File "/usr/local/lib/python2.7/dist-packages/django/utils/functional.py", line 32, in wrapper
    result = func(*args)
  File "/usr/local/lib/python2.7/dist-packages/django/core/urlresolvers.py", line 97, in get_callable
    mod = import_module(mod_name)
  File "/usr/local/lib/python2.7/dist-packages/django/utils/importlib.py", line 40, in import_module
    __import__(name)
  File "/usr/local/lib/python2.7/dist-packages/django/bin/myste/opt/views.py", line 5, in <module>
    from forms import UserForm
  File "/usr/local/lib/python2.7/dist-packages/django/bin/myste/opt/forms.py", line 6, in <module>
    class UserForm(forms.Form):
  File "/usr/local/lib/python2.7/dist-packages/django/bin/myste/opt/forms.py", line 8, in UserForm
    password = form.CharField(label='密码',widget=forms.PasswordInput())
NameError: name 'form' is not defined
2014-10-04 01:33:48,095 [Thread-6:-1246758080] [django.request:224] [ERROR]- Internal Server Error: /login
Traceback (most recent call last):
  File "/usr/local/lib/python2.7/dist-packages/django/core/handlers/base.py", line 88, in get_response
    response = middleware_method(request)
  File "/usr/local/lib/python2.7/dist-packages/django/middleware/common.py", line 72, in process_request
    urlresolvers.is_valid_path("%s/" % request.path_info, urlconf)):
  File "/usr/local/lib/python2.7/dist-packages/django/core/urlresolvers.py", line 596, in is_valid_path
    resolve(path, urlconf)
  File "/usr/local/lib/python2.7/dist-packages/django/core/urlresolvers.py", line 476, in resolve
    return get_resolver(urlconf).resolve(path)
  File "/usr/local/lib/python2.7/dist-packages/django/core/urlresolvers.py", line 339, in resolve
    sub_match = pattern.resolve(new_path)
  File "/usr/local/lib/python2.7/dist-packages/django/core/urlresolvers.py", line 223, in resolve
    return ResolverMatch(self.callback, args, kwargs, self.name)
  File "/usr/local/lib/python2.7/dist-packages/django/core/urlresolvers.py", line 230, in callback
    self._callback = get_callable(self._callback_str)
  File "/usr/local/lib/python2.7/dist-packages/django/utils/functional.py", line 32, in wrapper
    result = func(*args)
  File "/usr/local/lib/python2.7/dist-packages/django/core/urlresolvers.py", line 97, in get_callable
    mod = import_module(mod_name)
  File "/usr/local/lib/python2.7/dist-packages/django/utils/importlib.py", line 40, in import_module
    __import__(name)
  File "/usr/local/lib/python2.7/dist-packages/django/bin/myste/opt/views.py", line 5, in <module>
    from forms import UserForm
  File "/usr/local/lib/python2.7/dist-packages/django/bin/myste/opt/forms.py", line 2, in <module>
    from django import newforms as forms
ImportError: cannot import name newforms
2014-10-04 02:31:31,632 [Thread-8:-1257243840] [django.request:224] [ERROR]- Internal Server Error: /login
Traceback (most recent call last):
  File "/usr/local/lib/python2.7/dist-packages/django/core/handlers/base.py", line 88, in get_response
    response = middleware_method(request)
  File "/usr/local/lib/python2.7/dist-packages/django/middleware/common.py", line 72, in process_request
    urlresolvers.is_valid_path("%s/" % request.path_info, urlconf)):
  File "/usr/local/lib/python2.7/dist-packages/django/core/urlresolvers.py", line 596, in is_valid_path
    resolve(path, urlconf)
  File "/usr/local/lib/python2.7/dist-packages/django/core/urlresolvers.py", line 476, in resolve
    return get_resolver(urlconf).resolve(path)
  File "/usr/local/lib/python2.7/dist-packages/django/core/urlresolvers.py", line 339, in resolve
    sub_match = pattern.resolve(new_path)
  File "/usr/local/lib/python2.7/dist-packages/django/core/urlresolvers.py", line 223, in resolve
    return ResolverMatch(self.callback, args, kwargs, self.name)
  File "/usr/local/lib/python2.7/dist-packages/django/core/urlresolvers.py", line 230, in callback
    self._callback = get_callable(self._callback_str)
  File "/usr/local/lib/python2.7/dist-packages/django/utils/functional.py", line 32, in wrapper
    result = func(*args)
  File "/usr/local/lib/python2.7/dist-packages/django/core/urlresolvers.py", line 97, in get_callable
    mod = import_module(mod_name)
  File "/usr/local/lib/python2.7/dist-packages/django/utils/importlib.py", line 40, in import_module
    __import__(name)
  File "/usr/local/lib/python2.7/dist-packages/django/bin/myste/opt/views.py", line 5, in <module>
    from forms import UserForm
  File "/usr/local/lib/python2.7/dist-packages/django/bin/myste/opt/forms.py", line 2, in <module>
    from django import newforms as forms
ImportError: cannot import name newforms
2014-10-04 02:31:49,989 [Thread-10:-1246758080] [django.request:224] [ERROR]- Internal Server Error: /login
Traceback (most recent call last):
  File "/usr/local/lib/python2.7/dist-packages/django/core/handlers/base.py", line 88, in get_response
    response = middleware_method(request)
  File "/usr/local/lib/python2.7/dist-packages/django/middleware/common.py", line 72, in process_request
    urlresolvers.is_valid_path("%s/" % request.path_info, urlconf)):
  File "/usr/local/lib/python2.7/dist-packages/django/core/urlresolvers.py", line 596, in is_valid_path
    resolve(path, urlconf)
  File "/usr/local/lib/python2.7/dist-packages/django/core/urlresolvers.py", line 476, in resolve
    return get_resolver(urlconf).resolve(path)
  File "/usr/local/lib/python2.7/dist-packages/django/core/urlresolvers.py", line 339, in resolve
    sub_match = pattern.resolve(new_path)
  File "/usr/local/lib/python2.7/dist-packages/django/core/urlresolvers.py", line 223, in resolve
    return ResolverMatch(self.callback, args, kwargs, self.name)
  File "/usr/local/lib/python2.7/dist-packages/django/core/urlresolvers.py", line 230, in callback
    self._callback = get_callable(self._callback_str)
  File "/usr/local/lib/python2.7/dist-packages/django/utils/functional.py", line 32, in wrapper
    result = func(*args)
  File "/usr/local/lib/python2.7/dist-packages/django/core/urlresolvers.py", line 97, in get_callable
    mod = import_module(mod_name)
  File "/usr/local/lib/python2.7/dist-packages/django/utils/importlib.py", line 40, in import_module
    __import__(name)
  File "/usr/local/lib/python2.7/dist-packages/django/bin/myste/opt/views.py", line 5, in <module>
    from forms import UserForm
  File "/usr/local/lib/python2.7/dist-packages/django/bin/myste/opt/forms.py", line 2, in <module>
ImportError: cannot import name newforms
2014-10-04 02:31:52,293 [Thread-11:-1257243840] [django.request:224] [ERROR]- Internal Server Error: /login
Traceback (most recent call last):
  File "/usr/local/lib/python2.7/dist-packages/django/core/handlers/base.py", line 88, in get_response
    response = middleware_method(request)
  File "/usr/local/lib/python2.7/dist-packages/django/middleware/common.py", line 72, in process_request
    urlresolvers.is_valid_path("%s/" % request.path_info, urlconf)):
  File "/usr/local/lib/python2.7/dist-packages/django/core/urlresolvers.py", line 596, in is_valid_path
    resolve(path, urlconf)
  File "/usr/local/lib/python2.7/dist-packages/django/core/urlresolvers.py", line 476, in resolve
    return get_resolver(urlconf).resolve(path)
  File "/usr/local/lib/python2.7/dist-packages/django/core/urlresolvers.py", line 339, in resolve
    sub_match = pattern.resolve(new_path)
  File "/usr/local/lib/python2.7/dist-packages/django/core/urlresolvers.py", line 223, in resolve
    return ResolverMatch(self.callback, args, kwargs, self.name)
  File "/usr/local/lib/python2.7/dist-packages/django/core/urlresolvers.py", line 230, in callback
    self._callback = get_callable(self._callback_str)
  File "/usr/local/lib/python2.7/dist-packages/django/utils/functional.py", line 32, in wrapper
    result = func(*args)
  File "/usr/local/lib/python2.7/dist-packages/django/core/urlresolvers.py", line 97, in get_callable
    mod = import_module(mod_name)
  File "/usr/local/lib/python2.7/dist-packages/django/utils/importlib.py", line 40, in import_module
    __import__(name)
  File "/usr/local/lib/python2.7/dist-packages/django/bin/myste/opt/views.py", line 5, in <module>
    from forms import UserForm
  File "/usr/local/lib/python2.7/dist-packages/django/bin/myste/opt/forms.py", line 2, in <module>
ImportError: cannot import name newforms
2014-10-04 02:32:25,130 [Thread-1:-1246758080] [django.request:224] [ERROR]- Internal Server Error: /login
Traceback (most recent call last):
  File "/usr/local/lib/python2.7/dist-packages/django/core/handlers/base.py", line 88, in get_response
    response = middleware_method(request)
  File "/usr/local/lib/python2.7/dist-packages/django/middleware/common.py", line 72, in process_request
    urlresolvers.is_valid_path("%s/" % request.path_info, urlconf)):
  File "/usr/local/lib/python2.7/dist-packages/django/core/urlresolvers.py", line 596, in is_valid_path
    resolve(path, urlconf)
  File "/usr/local/lib/python2.7/dist-packages/django/core/urlresolvers.py", line 476, in resolve
    return get_resolver(urlconf).resolve(path)
  File "/usr/local/lib/python2.7/dist-packages/django/core/urlresolvers.py", line 339, in resolve
    sub_match = pattern.resolve(new_path)
  File "/usr/local/lib/python2.7/dist-packages/django/core/urlresolvers.py", line 223, in resolve
    return ResolverMatch(self.callback, args, kwargs, self.name)
  File "/usr/local/lib/python2.7/dist-packages/django/core/urlresolvers.py", line 230, in callback
    self._callback = get_callable(self._callback_str)
  File "/usr/local/lib/python2.7/dist-packages/django/utils/functional.py", line 32, in wrapper
    result = func(*args)
  File "/usr/local/lib/python2.7/dist-packages/django/core/urlresolvers.py", line 97, in get_callable
    mod = import_module(mod_name)
  File "/usr/local/lib/python2.7/dist-packages/django/utils/importlib.py", line 40, in import_module
    __import__(name)
  File "/usr/local/lib/python2.7/dist-packages/django/bin/myste/opt/views.py", line 5, in <module>
    from forms import UserForm
  File "/usr/local/lib/python2.7/dist-packages/django/bin/myste/opt/forms.py", line 2, in <module>
ImportError: cannot import name newforms
2014-10-04 02:34:27,056 [Thread-4:-1257243840] [django.request:224] [ERROR]- Internal Server Error: /login
Traceback (most recent call last):
  File "/usr/local/lib/python2.7/dist-packages/django/core/handlers/base.py", line 88, in get_response
    response = middleware_method(request)
  File "/usr/local/lib/python2.7/dist-packages/django/middleware/common.py", line 72, in process_request
    urlresolvers.is_valid_path("%s/" % request.path_info, urlconf)):
  File "/usr/local/lib/python2.7/dist-packages/django/core/urlresolvers.py", line 596, in is_valid_path
    resolve(path, urlconf)
  File "/usr/local/lib/python2.7/dist-packages/django/core/urlresolvers.py", line 476, in resolve
    return get_resolver(urlconf).resolve(path)
  File "/usr/local/lib/python2.7/dist-packages/django/core/urlresolvers.py", line 339, in resolve
    sub_match = pattern.resolve(new_path)
  File "/usr/local/lib/python2.7/dist-packages/django/core/urlresolvers.py", line 223, in resolve
    return ResolverMatch(self.callback, args, kwargs, self.name)
  File "/usr/local/lib/python2.7/dist-packages/django/core/urlresolvers.py", line 230, in callback
    self._callback = get_callable(self._callback_str)
  File "/usr/local/lib/python2.7/dist-packages/django/utils/functional.py", line 32, in wrapper
    result = func(*args)
  File "/usr/local/lib/python2.7/dist-packages/django/core/urlresolvers.py", line 97, in get_callable
    mod = import_module(mod_name)
  File "/usr/local/lib/python2.7/dist-packages/django/utils/importlib.py", line 40, in import_module
    __import__(name)
  File "/usr/local/lib/python2.7/dist-packages/django/bin/myste/opt/views.py", line 5, in <module>
    from forms import UserForm
  File "/usr/local/lib/python2.7/dist-packages/django/bin/myste/opt/forms.py", line 2, in <module>
    from django import newforms as forms
ImportError: cannot import name newforms
2014-10-04 02:34:29,781 [Thread-5:-1246758080] [django.request:224] [ERROR]- Internal Server Error: /login
Traceback (most recent call last):
  File "/usr/local/lib/python2.7/dist-packages/django/core/handlers/base.py", line 88, in get_response
    response = middleware_method(request)
  File "/usr/local/lib/python2.7/dist-packages/django/middleware/common.py", line 72, in process_request
    urlresolvers.is_valid_path("%s/" % request.path_info, urlconf)):
  File "/usr/local/lib/python2.7/dist-packages/django/core/urlresolvers.py", line 596, in is_valid_path
    resolve(path, urlconf)
  File "/usr/local/lib/python2.7/dist-packages/django/core/urlresolvers.py", line 476, in resolve
    return get_resolver(urlconf).resolve(path)
  File "/usr/local/lib/python2.7/dist-packages/django/core/urlresolvers.py", line 339, in resolve
    sub_match = pattern.resolve(new_path)
  File "/usr/local/lib/python2.7/dist-packages/django/core/urlresolvers.py", line 223, in resolve
    return ResolverMatch(self.callback, args, kwargs, self.name)
  File "/usr/local/lib/python2.7/dist-packages/django/core/urlresolvers.py", line 230, in callback
    self._callback = get_callable(self._callback_str)
  File "/usr/local/lib/python2.7/dist-packages/django/utils/functional.py", line 32, in wrapper
    result = func(*args)
  File "/usr/local/lib/python2.7/dist-packages/django/core/urlresolvers.py", line 97, in get_callable
    mod = import_module(mod_name)
  File "/usr/local/lib/python2.7/dist-packages/django/utils/importlib.py", line 40, in import_module
    __import__(name)
  File "/usr/local/lib/python2.7/dist-packages/django/bin/myste/opt/views.py", line 5, in <module>
    from forms import UserForm
  File "/usr/local/lib/python2.7/dist-packages/django/bin/myste/opt/forms.py", line 2, in <module>
    from django import newforms as forms
ImportError: cannot import name newforms
2014-10-04 02:36:33,004 [Thread-7:-1257243840] [django.request:224] [ERROR]- Internal Server Error: /login
Traceback (most recent call last):
  File "/usr/local/lib/python2.7/dist-packages/django/core/handlers/base.py", line 88, in get_response
    response = middleware_method(request)
  File "/usr/local/lib/python2.7/dist-packages/django/middleware/common.py", line 72, in process_request
    urlresolvers.is_valid_path("%s/" % request.path_info, urlconf)):
  File "/usr/local/lib/python2.7/dist-packages/django/core/urlresolvers.py", line 596, in is_valid_path
    resolve(path, urlconf)
  File "/usr/local/lib/python2.7/dist-packages/django/core/urlresolvers.py", line 476, in resolve
    return get_resolver(urlconf).resolve(path)
  File "/usr/local/lib/python2.7/dist-packages/django/core/urlresolvers.py", line 339, in resolve
    sub_match = pattern.resolve(new_path)
  File "/usr/local/lib/python2.7/dist-packages/django/core/urlresolvers.py", line 223, in resolve
    return ResolverMatch(self.callback, args, kwargs, self.name)
  File "/usr/local/lib/python2.7/dist-packages/django/core/urlresolvers.py", line 230, in callback
    self._callback = get_callable(self._callback_str)
  File "/usr/local/lib/python2.7/dist-packages/django/utils/functional.py", line 32, in wrapper
    result = func(*args)
  File "/usr/local/lib/python2.7/dist-packages/django/core/urlresolvers.py", line 97, in get_callable
    mod = import_module(mod_name)
  File "/usr/local/lib/python2.7/dist-packages/django/utils/importlib.py", line 40, in import_module
    __import__(name)
  File "/usr/local/lib/python2.7/dist-packages/django/bin/myste/opt/views.py", line 5, in <module>
    from forms import UserForm
  File "/usr/local/lib/python2.7/dist-packages/django/bin/myste/opt/forms.py", line 2, in <module>
    from django import newforms as forms
ImportError: cannot import name newforms
2014-10-04 02:36:35,945 [Thread-8:-1246758080] [django.request:224] [ERROR]- Internal Server Error: /login
Traceback (most recent call last):
  File "/usr/local/lib/python2.7/dist-packages/django/core/handlers/base.py", line 88, in get_response
    response = middleware_method(request)
  File "/usr/local/lib/python2.7/dist-packages/django/middleware/common.py", line 72, in process_request
    urlresolvers.is_valid_path("%s/" % request.path_info, urlconf)):
  File "/usr/local/lib/python2.7/dist-packages/django/core/urlresolvers.py", line 596, in is_valid_path
    resolve(path, urlconf)
  File "/usr/local/lib/python2.7/dist-packages/django/core/urlresolvers.py", line 476, in resolve
    return get_resolver(urlconf).resolve(path)
  File "/usr/local/lib/python2.7/dist-packages/django/core/urlresolvers.py", line 339, in resolve
    sub_match = pattern.resolve(new_path)
  File "/usr/local/lib/python2.7/dist-packages/django/core/urlresolvers.py", line 223, in resolve
    return ResolverMatch(self.callback, args, kwargs, self.name)
  File "/usr/local/lib/python2.7/dist-packages/django/core/urlresolvers.py", line 230, in callback
    self._callback = get_callable(self._callback_str)
  File "/usr/local/lib/python2.7/dist-packages/django/utils/functional.py", line 32, in wrapper
    result = func(*args)
  File "/usr/local/lib/python2.7/dist-packages/django/core/urlresolvers.py", line 97, in get_callable
    mod = import_module(mod_name)
  File "/usr/local/lib/python2.7/dist-packages/django/utils/importlib.py", line 40, in import_module
    __import__(name)
  File "/usr/local/lib/python2.7/dist-packages/django/bin/myste/opt/views.py", line 5, in <module>
    from forms import UserForm
  File "/usr/local/lib/python2.7/dist-packages/django/bin/myste/opt/forms.py", line 2, in <module>
    from django import newforms as forms
ImportError: cannot import name newforms
2014-10-04 02:41:16,093 [Thread-12:-1246758080] [django.request:224] [ERROR]- Internal Server Error: /login/
Traceback (most recent call last):
  File "/usr/local/lib/python2.7/dist-packages/django/core/handlers/base.py", line 112, in get_response
    response = wrapped_callback(request, *callback_args, **callback_kwargs)
  File "/usr/local/lib/python2.7/dist-packages/django/bin/myste/opt/views.py", line 195, in login
    username = request.POST['username']
  File "/usr/local/lib/python2.7/dist-packages/django/utils/datastructures.py", line 301, in __getitem__
    raise MultiValueDictKeyError(repr(key))
MultiValueDictKeyError: "'username'"
2014-10-04 02:41:19,906 [Thread-13:-1246758080] [django.request:224] [ERROR]- Internal Server Error: /login/
Traceback (most recent call last):
  File "/usr/local/lib/python2.7/dist-packages/django/core/handlers/base.py", line 112, in get_response
    response = wrapped_callback(request, *callback_args, **callback_kwargs)
  File "/usr/local/lib/python2.7/dist-packages/django/bin/myste/opt/views.py", line 195, in login
    username = request.POST['username']
  File "/usr/local/lib/python2.7/dist-packages/django/utils/datastructures.py", line 301, in __getitem__
    raise MultiValueDictKeyError(repr(key))
MultiValueDictKeyError: "'username'"
2014-10-04 03:03:55,978 [Thread-7:-1256195264] [django.request:224] [ERROR]- Internal Server Error: /login/
Traceback (most recent call last):
  File "/usr/local/lib/python2.7/dist-packages/django/core/handlers/base.py", line 112, in get_response
    response = wrapped_callback(request, *callback_args, **callback_kwargs)
  File "/usr/local/lib/python2.7/dist-packages/django/bin/myste/opt/views.py", line 195, in login
    username = request.POST['username']
  File "/usr/local/lib/python2.7/dist-packages/django/utils/datastructures.py", line 301, in __getitem__
    raise MultiValueDictKeyError(repr(key))
MultiValueDictKeyError: "'username'"
2014-10-04 06:46:32,016 [Thread-1:-1246024896] [django.request:224] [ERROR]- Internal Server Error: /login/
Traceback (most recent call last):
  File "/usr/local/lib/python2.7/dist-packages/django/core/handlers/base.py", line 99, in get_response
    resolver_match = resolver.resolve(request.path_info)
  File "/usr/local/lib/python2.7/dist-packages/django/core/urlresolvers.py", line 337, in resolve
    for pattern in self.url_patterns:
  File "/usr/local/lib/python2.7/dist-packages/django/core/urlresolvers.py", line 365, in url_patterns
    patterns = getattr(self.urlconf_module, "urlpatterns", self.urlconf_module)
  File "/usr/local/lib/python2.7/dist-packages/django/core/urlresolvers.py", line 360, in urlconf_module
    self._urlconf_module = import_module(self.urlconf_name)
  File "/usr/local/lib/python2.7/dist-packages/django/utils/importlib.py", line 40, in import_module
    __import__(name)
  File "/usr/local/lib/python2.7/dist-packages/django/bin/myste/myste/urls.py", line 4, in <module>
    admin.autodiscover()
  File "/usr/local/lib/python2.7/dist-packages/django/contrib/admin/__init__.py", line 29, in autodiscover
    import_module('%s.admin' % app)
  File "/usr/local/lib/python2.7/dist-packages/django/utils/importlib.py", line 40, in import_module
    __import__(name)
  File "/usr/local/lib/python2.7/dist-packages/django/bin/myste/opt/admin.py", line 7, in <module>
    admin.site.register(User,UserAdmin)
NameError: name 'User' is not defined
2014-10-04 06:47:56,639 [Thread-4:-1256195264] [django.request:224] [ERROR]- Internal Server Error: /login/
Traceback (most recent call last):
  File "/usr/local/lib/python2.7/dist-packages/django/core/handlers/base.py", line 112, in get_response
    response = wrapped_callback(request, *callback_args, **callback_kwargs)
  File "/usr/local/lib/python2.7/dist-packages/django/bin/myste/opt/views.py", line 195, in login
    username = request.POST['username']
  File "/usr/local/lib/python2.7/dist-packages/django/utils/datastructures.py", line 301, in __getitem__
    raise MultiValueDictKeyError(repr(key))
MultiValueDictKeyError: "'username'"
2014-10-04 06:49:46,106 [Thread-6:-1246024896] [django.request:224] [ERROR]- Internal Server Error: /login/
Traceback (most recent call last):
  File "/usr/local/lib/python2.7/dist-packages/django/core/handlers/base.py", line 112, in get_response
    response = wrapped_callback(request, *callback_args, **callback_kwargs)
  File "/usr/local/lib/python2.7/dist-packages/django/bin/myste/opt/views.py", line 195, in login
    username = request.POST['username']
  File "/usr/local/lib/python2.7/dist-packages/django/utils/datastructures.py", line 301, in __getitem__
    raise MultiValueDictKeyError(repr(key))
MultiValueDictKeyError: "'username'"
